Workbook

Sheet B.CJ.A0
C2: Min | J2: Distance (nm) | Q2: Fuel (lbs)
B3: Weight at Descent | C3: 9000 | D3: 8000 | E3: 7000 | F3: KIAS | I3: Weight at Descent | J3: 9000 | K3: 8000 | L3: 7000 | M3: KIAS | P3: Weight at Descent | Q3: 9000 | R3: 8000 | S3: 7000 | T3: KIAS
A4: Altitude | B4: 31000 | C4: 15.5 | D4: 15.5 | E4: 15.5 | F4: 250 | H4: Altitude | I4: 31000 | J4: 82 | K4: 82 | L4: 82 | M4: 250 | O4: Altitude | P4: 31000 | Q4: 152 | R4: 145 | S4: 140 | T4: 250
B5: =B4+2000 -> 33000 | C5: 16.5 | D5: 16.5 | E5: 16.5 | F5: 238 | I5: =I4+2000 -> 33000 | J5: 88 | K5: 88 | L5: 88 | M5: 238 | P5: =P4+2000 -> 33000 | Q5: 163 | R5: 155 | S5: 149 | T5: 238
B6: =B5+2000 -> 35000 | C6: 17.5 | D6: 17.5 | E6: 17.5 | F6: 227 | I6: =I5+2000 -> 35000 | J6: 95 | K6: 95 | L6: 95 | M6: 227 | P6: =P5+2000 -> 35000 | Q6: 173 | R6: 164 | S6: 158 | T6: 227
B7: =B6+2000 -> 37000 | C7: 18.5 | D7: 18.5 | E7: 18.5 | F7: 216 | I7: =I6+2000 -> 37000 | J7: 101 | K7: 101 | L7: 101 | M7: 216 | P7: =P6+2000 -> 37000 | Q7: 184 | R7: 174 | S7: 166 | T7: 216
B8: =B7+2000 -> 39000 | C8: 19.5 | D8: 19.5 | E8: 19.5 | F8: 206 | I8: =I7+2000 -> 39000 | J8: 107 | K8: 107 | L8: 107 | M8: 206 | P8: =P7+2000 -> 39000 | Q8: 195 | R8: 183 | S8: 175 | T8: 206
B9: =B8+2000 -> 41000 | C9: 20.4 | D9: 20.4 | E9: 20.4 | F9: 196 | I9: =I8+2000 -> 41000 | J9: 113 | K9: 114 | L9: 114 | M9: 196 | P9: =P8+2000 -> 41000 | Q9: 205 | R9: 193 | S9: 183 | T9: 196
B12: HIGH SPEED DESCENT
C14: Min | J14: Distance (nm) | Q14: Fuel (lbs)
B15: Weight at Descent | C15: 9000 | D15: 8000 | E15: 7000 | F15: KIAS | I15: Weight at Descent | J15: 9000 | K15: 8000 | L15: 7000 | M15: KIAS | P15: Weight at Descent | Q15: 9000 | R15: 8000 | S15: 7000 | T15: KIAS
A16: Altitude | B16: 31000 | C16: 10.3 | D16: 10.3 | E16: 10.3 | F16: 250 | H16: Altitude | I16: 31000 | J16: 54 | K16: 54 | L16: 54 | M16: 250 | O16: Altitude | P16: 31000 | Q16: 67 | R16: 66 | S16: 66 | T16: 250
B17: =B16+2000 -> 33000 | C17: 11 | D17: 11 | E17: 11 | F17: 238 | I17: =I16+2000 -> 33000 | J17: 59 | K17: 59 | L17: 59 | M17: 238 | P17: =P16+2000 -> 33000 | Q17: 73 | R17: 71 | S17: 71 | T17: 238
B18: =B17+2000 -> 35000 | C18: 11.7 | D18: 11.7 | E18: 11.7 | F18: 227 | I18: =I17+2000 -> 35000 | J18: 63 | K18: 63 | L18: 63 | M18: 227 | P18: =P17+2000 -> 35000 | Q18: 79 | R18: 77 | S18: 76 | T18: 227
B19: =B18+2000 -> 37000 | C19: 12.3 | D19: 12.3 | E19: 12.3 | F19: 216 | I19: =I18+2000 -> 37000 | J19: 67 | K19: 67 | L19: 67 | M19: 216 | P19: =P18+2000 -> 37000 | Q19: 84 | R19: 82 | S19: 81 | T19: 216
B20: =B19+2000 -> 39000 | C20: 13 | D20: 13 | E20: 13 | F20: 206 | I20: =I19+2000 -> 39000 | J20: 71 | K20: 71 | L20: 71 | M20: 206 | P20: =P19+2000 -> 39000 | Q20: 90 | R20: 86 | S20: 85 | T20: 206
B21: =B20+2000 -> 41000 | C21: 13.7 | D21: 13.7 | E21: 13.7 | F21: 196 | I21: =I20+2000 -> 41000 | J21: 76 | K21: 76 | L21: 76 | M21: 196 | P21: =P20+2000 -> 41000 | Q21: 96 | R21: 91 | S21: 90 | T21: 196

Sheet M.CJ.A0
C2: Min | J2: Distance (nm) | Q2: Fuel (lbs)
B3: Weight at Descent | C3: 9000 | D3: 8000 | E3: 7000 | F3: KIAS | I3: Weight at Descent | J3: 9000 | K3: 8000 | L3: 7000 | M3: KIAS | P3: Weight at Descent | Q3: 9000 | R3: 8000 | S3: 7000 | T3: KIAS
A4: Altitude | B4: 31000 | C4: 15.5 | D4: 15.5 | E4: 15.5 | F4: 250 | H4: Altitude | I4: 31000 | J4: 82 | K4: 82 | L4: 82 | M4: 250 | O4: Altitude | P4: 31000 | Q4: 152 | R4: 145 | S4: 140 | T4: 250
B5: =B4+2000 -> 33000 | C5: 16.5 | D5: 16.5 | E5: 16.5 | F5: 238 | I5: =I4+2000 -> 33000 | J5: 88 | K5: 88 | L5: 88 | M5: 238 | P5: =P4+2000 -> 33000 | Q5: 163 | R5: 155 | S5: 149 | T5: 238
B6: =B5+2000 -> 35000 | C6: 17.5 | D6: 17.5 | E6: 17.5 | F6: 227 | I6: =I5+2000 -> 35000 | J6: 95 | K6: 95 | L6: 95 | M6: 227 | P6: =P5+2000 -> 35000 | Q6: 173 | R6: 164 | S6: 158 | T6: 227
B7: =B6+2000 -> 37000 | C7: 18.5 | D7: 18.5 | E7: 18.5 | F7: 216 | I7: =I6+2000 -> 37000 | J7: 101 | K7: 101 | L7: 101 | M7: 216 | P7: =P6+2000 -> 37000 | Q7: 184 | R7: 174 | S7: 166 | T7: 216
B8: =B7+2000 -> 39000 | C8: 19.5 | D8: 19.5 | E8: 19.5 | F8: 206 | I8: =I7+2000 -> 39000 | J8: 107 | K8: 107 | L8: 107 | M8: 206 | P8: =P7+2000 -> 39000 | Q8: 195 | R8: 183 | S8: 175 | T8: 206
B9: =B8+2000 -> 41000 | C9: 20.4 | D9: 20.4 | E9: 20.4 | F9: 196 | I9: =I8+2000 -> 41000 | J9: 113 | K9: 114 | L9: 114 | M9: 196 | P9: =P8+2000 -> 41000 | Q9: 205 | R9: 193 | S9: 183 | T9: 196
B12: HIGH SPEED DESCENT
C14: Min | J14: Distance (nm) | Q14: Fuel (lbs)
B15: Weight at Descent | C15: 9000 | D15: 8000 | E15: 7000 | F15: KIAS | I15: Weight at Descent | J15: 9000 | K15: 8000 | L15: 7000 | M15: KIAS | P15: Weight at Descent | Q15: 9000 | R15: 8000 | S15: 7000 | T15: KIAS
A16: Altitude | B16: 31000 | C16: 10.3 | D16: 10.3 | E16: 10.3 | F16: 250 | H16: Altitude | I16: 31000 | J16: 54 | K16: 54 | L16: 54 | M16: 250 | O16: Altitude | P16: 31000 | Q16: 67 | R16: 66 | S16: 66 | T16: 250
B17: =B16+2000 -> 33000 | C17: 11 | D17: 11 | E17: 11 | F17: 238 | I17: =I16+2000 -> 33000 | J17: 59 | K17: 59 | L17: 59 | M17: 238 | P17: =P16+2000 -> 33000 | Q17: 73 | R17: 71 | S17: 71 | T17: 238
B18: =B17+2000 -> 35000 | C18: 11.7 | D18: 11.7 | E18: 11.7 | F18: 227 | I18: =I17+2000 -> 35000 | J18: 63 | K18: 63 | L18: 63 | M18: 227 | P18: =P17+2000 -> 35000 | Q18: 79 | R18: 77 | S18: 76 | T18: 227
B19: =B18+2000 -> 37000 | C19: 12.3 | D19: 12.3 | E19: 12.3 | F19: 216 | I19: =I18+2000 -> 37000 | J19: 67 | K19: 67 | L19: 67 | M19: 216 | P19: =P18+2000 -> 37000 | Q19: 84 | R19: 82 | S19: 81 | T19: 216
B20: =B19+2000 -> 39000 | C20: 13 | D20: 13 | E20: 13 | F20: 206 | I20: =I19+2000 -> 39000 | J20: 71 | K20: 71 | L20: 71 | M20: 206 | P20: =P19+2000 -> 39000 | Q20: 90 | R20: 86 | S20: 85 | T20: 206
B21: =B20+2000 -> 41000 | C21: 13.7 | D21: 13.7 | E21: 13.7 | F21: 196 | I21: =I20+2000 -> 41000 | J21: 76 | K21: 76 | L21: 76 | M21: 196 | P21: =P20+2000 -> 41000 | Q21: 96 | R21: 91 | S21: 90 | T21: 196

Sheet B.CJ.A1
C2: Min | J2: Distance (nm) | Q2: Fuel (lbs)
B3: Weight at Descent | C3: 9000 | D3: 8000 | E3: 7000 | F3: KIAS | I3: Weight at Descent | J3: 9000 | K3: 8000 | L3: 7000 | M3: KIAS | P3: Weight at Descent | Q3: 9000 | R3: 8000 | S3: 7000 | T3: KIAS
A4: Altitude | B4: 31000 | C4: 15.5 | D4: 15.5 | E4: 15.5 | F4: 250 | H4: Altitude | I4: 31000 | J4: 82 | K4: 82 | L4: 82 | M4: 250 | O4: Altitude | P4: 31000 | Q4: 168 | R4: 161 | S4: 156 | T4: 250
B5: =B4+2000 -> 33000 | C5: 16.5 | D5: 16.5 | E5: 16.5 | F5: 238 | I5: =I4+2000 -> 33000 | J5: 88 | K5: 88 | L5: 88 | M5: 238 | P5: =P4+2000 -> 33000 | Q5: 180 | R5: 172 | S5: 166 | T5: 238
B6: =B5+2000 -> 35000 | C6: 17.5 | D6: 17.5 | E6: 17.5 | F6: 227 | I6: =I5+2000 -> 35000 | J6: 95 | K6: 95 | L6: 95 | M6: 227 | P6: =P5+2000 -> 35000 | Q6: 192 | R6: 183 | S6: 176 | T6: 227
B7: =B6+2000 -> 37000 | C7: 18.4 | D7: 18.5 | E7: 18.5 | F7: 216 | I7: =I6+2000 -> 37000 | J7: 100 | K7: 101 | L7: 101 | M7: 216 | P7: =P6+2000 -> 37000 | Q7: 203 | R7: 193 | S7: 186 | T7: 216
B8: =B7+2000 -> 39000 | C8: 19.1 | D8: 19.4 | E8: 19.5 | F8: 206 | I8: =I7+2000 -> 39000 | J8: 105 | K8: 107 | L8: 107 | M8: 206 | P8: =P7+2000 -> 39000 | Q8: 210 | R8: 202 | S8: 195 | T8: 206
B9: =B8+2000 -> 41000 | C9: 19.7 | D9: 20 | E9: 20.3 | F9: 196 | I9: =I8+2000 -> 41000 | J9: 109 | K9: 111 | L9: 112 | M9: 196 | P9: =P8+2000 -> 41000 | Q9: 214 | R9: 208 | S9: 202 | T9: 196
B13: HIGH SPEED DESCENT
C15: Min | J15: Distance (nm) | Q15: Fuel (lbs)
B16: Weight at Descent | C16: 9000 | D16: 8000 | E16: 7000 | F16: KIAS | I16: Weight at Descent | J16: 9000 | K16: 8000 | L16: 7000 | M16: KIAS | P16: Weight at Descent | Q16: 9000 | R16: 8000 | S16: 7000 | T16: KIAS
A17: Altitude | B17: 31000 | C17: 10.3 | D17: 10.3 | E17: 10.3 | F17: 250 | H17: Altitude | I17: 31000 | J17: 54 | K17: 54 | L17: 54 | M17: 250 | O17: Altitude | P17: 31000 | Q17: 77 | R17: 75 | S17: 76 | T17: 250
B18: =B17+2000 -> 33000 | C18: 11 | D18: 11 | E18: 11 | F18: 238 | I18: =I17+2000 -> 33000 | J18: 59 | K18: 59 | L18: 59 | M18: 238 | P18: =P17+2000 -> 33000 | Q18: 83 | R18: 82 | S18: 82 | T18: 238
B19: =B18+2000 -> 35000 | C19: 11.7 | D19: 11.7 | E19: 11.7 | F19: 227 | I19: =I18+2000 -> 35000 | J19: 63 | K19: 63 | L19: 63 | M19: 227 | P19: =P18+2000 -> 35000 | Q19: 90 | R19: 88 | S19: 87 | T19: 227
B20: =B19+2000 -> 37000 | C20: 12.3 | D20: 12.3 | E20: 12.3 | F20: 216 | I20: =I19+2000 -> 37000 | J20: 67 | K20: 67 | L20: 67 | M20: 216 | P20: =P19+2000 -> 37000 | Q20: 96 | R20: 93 | S20: 93 | T20: 216
B21: =B20+2000 -> 39000 | C21: 13 | D21: 13 | E21: 13 | F21: 206 | I21: =I20+2000 -> 39000 | J21: 71 | K21: 71 | L21: 71 | M21: 206 | P21: =P20+2000 -> 39000 | Q21: 102 | R21: 99 | S21: 98 | T21: 206
B22: =B21+2000 -> 41000 | C22: 13.6 | D22: 13.6 | E22: 13.7 | F22: 196 | I22: =I21+2000 -> 41000 | J22: 75 | K22: 76 | L22: 76 | M22: 196 | P22: =P21+2000 -> 41000 | Q22: 107 | R22: 104 | S22: 103 | T22: 196

Sheet M.CJ.A1
C2: Min | J2: Distance (nm) | Q2: Fuel (lbs)
B3: Weight at Descent | C3: 9000 | D3: 8000 | E3: 7000 | F3: KIAS | I3: Weight at Descent | J3: 9000 | K3: 8000 | L3: 7000 | M3: KIAS | P3: Weight at Descent | Q3: 9000 | R3: 8000 | S3: 7000 | T3: KIAS
A4: Altitude | B4: 31000 | C4: 15.5 | D4: 15.5 | E4: 15.5 | F4: 250 | H4: Altitude | I4: 31000 | J4: 82 | K4: 82 | L4: 82 | M4: 250 | O4: Altitude | P4: 31000 | Q4: 168 | R4: 161 | S4: 156 | T4: 250
B5: =B4+2000 -> 33000 | C5: 16.5 | D5: 16.5 | E5: 16.5 | F5: 238 | I5: =I4+2000 -> 33000 | J5: 88 | K5: 88 | L5: 88 | M5: 238 | P5: =P4+2000 -> 33000 | Q5: 180 | R5: 172 | S5: 166 | T5: 238
B6: =B5+2000 -> 35000 | C6: 17.5 | D6: 17.5 | E6: 17.5 | F6: 227 | I6: =I5+2000 -> 35000 | J6: 95 | K6: 95 | L6: 95 | M6: 227 | P6: =P5+2000 -> 35000 | Q6: 192 | R6: 183 | S6: 176 | T6: 227
B7: =B6+2000 -> 37000 | C7: 18.4 | D7: 18.5 | E7: 18.5 | F7: 216 | I7: =I6+2000 -> 37000 | J7: 100 | K7: 101 | L7: 101 | M7: 216 | P7: =P6+2000 -> 37000 | Q7: 203 | R7: 193 | S7: 186 | T7: 216
B8: =B7+2000 -> 39000 | C8: 19.1 | D8: 19.4 | E8: 19.5 | F8: 206 | I8: =I7+2000 -> 39000 | J8: 105 | K8: 107 | L8: 107 | M8: 206 | P8: =P7+2000 -> 39000 | Q8: 210 | R8: 202 | S8: 195 | T8: 206
B9: =B8+2000 -> 41000 | C9: 19.7 | D9: 20 | E9: 20.3 | F9: 196 | I9: =I8+2000 -> 41000 | J9: 109 | K9: 111 | L9: 112 | M9: 196 | P9: =P8+2000 -> 41000 | Q9: 214 | R9: 208 | S9: 202 | T9: 196
B13: HIGH SPEED DESCENT
C15: Min | J15: Distance (nm) | Q15: Fuel (lbs)
B16: Weight at Descent | C16: 9000 | D16: 8000 | E16: 7000 | F16: KIAS | I16: Weight at Descent | J16: 9000 | K16: 8000 | L16: 7000 | M16: KIAS | P16: Weight at Descent | Q16: 9000 | R16: 8000 | S16: 7000 | T16: KIAS
A17: Altitude | B17: 31000 | C17: 10.3 | D17: 10.3 | E17: 10.3 | F17: 250 | H17: Altitude | I17: 31000 | J17: 54 | K17: 54 | L17: 54 | M17: 250 | O17: Altitude | P17: 31000 | Q17: 77 | R17: 75 | S17: 76 | T17: 250
B18: =B17+2000 -> 33000 | C18: 11 | D18: 11 | E18: 11 | F18: 238 | I18: =I17+2000 -> 33000 | J18: 59 | K18: 59 | L18: 59 | M18: 238 | P18: =P17+2000 -> 33000 | Q18: 83 | R18: 82 | S18: 82 | T18: 238
B19: =B18+2000 -> 35000 | C19: 11.7 | D19: 11.7 | E19: 11.7 | F19: 227 | I19: =I18+2000 -> 35000 | J19: 63 | K19: 63 | L19: 63 | M19: 227 | P19: =P18+2000 -> 35000 | Q19: 90 | R19: 88 | S19: 87 | T19: 227
B20: =B19+2000 -> 37000 | C20: 12.3 | D20: 12.3 | E20: 12.3 | F20: 216 | I20: =I19+2000 -> 37000 | J20: 67 | K20: 67 | L20: 67 | M20: 216 | P20: =P19+2000 -> 37000 | Q20: 96 | R20: 93 | S20: 93 | T20: 216
B21: =B20+2000 -> 39000 | C21: 13 | D21: 13 | E21: 13 | F21: 206 | I21: =I20+2000 -> 39000 | J21: 71 | K21: 71 | L21: 71 | M21: 206 | P21: =P20+2000 -> 39000 | Q21: 102 | R21: 99 | S21: 98 | T21: 206
B22: =B21+2000 -> 41000 | C22: 13.6 | D22: 13.6 | E22: 13.7 | F22: 196 | I22: =I21+2000 -> 41000 | J22: 75 | K22: 76 | L22: 76 | M22: 196 | P22: =P21+2000 -> 41000 | Q22: 107 | R22: 104 | S22: 103 | T22: 196

Sheet B.CJ1.A0
C2: Min | J2: Distance (nm) | Q2: Fuel (lbs)
B3: Weight at Descent | C3: wt not specified | F3: KIAS | I3: Weight at Descent | J3: wt not specified | M3: KIAS | P3: Weight at Descent | Q3: wt not specified | T3: KIAS
A4: Altitude | B4: 31000 | C4: 15.5 | D4: 15.5 | E4: 15.5 | F4: 250 | H4: Altitude | I4: 31000 | J4: 81 | K4: 81 | L4: 81 | M4: 250 | O4: Altitude | P4: 31000 | Q4: 151 | R4: 151 | S4: 151 | T4: 250
B5: =B4+2000 -> 33000 | C5: 16.5 | D5: 16.5 | E5: 16.5 | F5: 238 | I5: =I4+2000 -> 33000 | J5: 88 | K5: 88 | L5: 88 | M5: 238 | P5: =P4+2000 -> 33000 | Q5: 161 | R5: 161 | S5: 161 | T5: 238
B6: =B5+2000 -> 35000 | C6: 17.5 | D6: 17.5 | E6: 17.5 | F6: 227 | I6: =I5+2000 -> 35000 | J6: 94 | K6: 94 | L6: 94 | M6: 227 | P6: =P5+2000 -> 35000 | Q6: 170 | R6: 170 | S6: 170 | T6: 227
B7: =B6+2000 -> 37000 | C7: 18.5 | D7: 18.5 | E7: 18.5 | F7: 216 | I7: =I6+2000 -> 37000 | J7: 101 | K7: 101 | L7: 101 | M7: 216 | P7: =P6+2000 -> 37000 | Q7: 180 | R7: 180 | S7: 180 | T7: 216
B8: =B7+2000 -> 39000 | C8: 19.5 | D8: 19.5 | E8: 19.5 | F8: 206 | I8: =I7+2000 -> 39000 | J8: 107 | K8: 107 | L8: 107 | M8: 206 | P8: =P7+2000 -> 39000 | Q8: 189 | R8: 189 | S8: 189 | T8: 206
B9: =B8+2000 -> 41000 | C9: 20.5 | D9: 20.5 | E9: 20.5 | F9: 196 | I9: =I8+2000 -> 41000 | J9: 114 | K9: 114 | L9: 114 | M9: 196 | P9: =P8+2000 -> 41000 | Q9: 199 | R9: 199 | S9: 199 | T9: 196
B12: HIGH SPEED DESCENT
C14: Min | J14: Distance (nm) | Q14: Fuel (lbs)
B15: Weight at Descent | C15: wt not specified | F15: KIAS | I15: Weight at Descent | J15: wt not specified | M15: KIAS | P15: Weight at Descent | Q15: wt not specified | T15: KIAS
A16: Altitude | B16: 31000 | C16: 10.3 | D16: 10.3 | E16: 10.3 | F16: 250 | H16: Altitude | I16: 31000 | J16: 54 | K16: 54 | L16: 54 | M16: 250 | O16: Altitude | P16: 31000 | Q16: 70 | R16: 70 | S16: 70 | T16: 250
B17: =B16+2000 -> 33000 | C17: 11 | D17: 11 | E17: 11 | F17: 238 | I17: =I16+2000 -> 33000 | J17: 58 | K17: 58 | L17: 58 | M17: 238 | P17: =P16+2000 -> 33000 | Q17: 75 | R17: 75 | S17: 75 | T17: 238
B18: =B17+2000 -> 35000 | C18: 11.7 | D18: 11.7 | E18: 11.7 | F18: 227 | I18: =I17+2000 -> 35000 | J18: 63 | K18: 63 | L18: 63 | M18: 227 | P18: =P17+2000 -> 35000 | Q18: 80 | R18: 80 | S18: 80 | T18: 227
B19: =B18+2000 -> 37000 | C19: 12.3 | D19: 12.3 | E19: 12.3 | F19: 216 | I19: =I18+2000 -> 37000 | J19: 67 | K19: 67 | L19: 67 | M19: 216 | P19: =P18+2000 -> 37000 | Q19: 85 | R19: 85 | S19: 85 | T19: 216
B20: =B19+2000 -> 39000 | C20: 13 | D20: 13 | E20: 13 | F20: 206 | I20: =I19+2000 -> 39000 | J20: 71 | K20: 71 | L20: 71 | M20: 206 | P20: =P19+2000 -> 39000 | Q20: 90 | R20: 90 | S20: 90 | T20: 206
B21: =B20+2000 -> 41000 | C21: 13.7 | D21: 13.7 | E21: 13.7 | F21: 196 | I21: =I20+2000 -> 41000 | J21: 76 | K21: 76 | L21: 76 | M21: 196 | P21: =P20+2000 -> 41000 | Q21: 95 | R21: 95 | S21: 95 | T21: 196

Sheet M.CJ1.A0
C2: Min | J2: Distance (nm) | Q2: Fuel (lbs)
B3: Weight at Descent | C3: not specified | F3: KIAS | I3: Weight at Descent | J3: not specified | M3: KIAS | P3: Weight at Descent | Q3: not specified | T3: KIAS
A4: Altitude | B4: 31000 | C4: 15.5 | D4: 15.5 | E4: 15.5 | F4: 250 | H4: Altitude | I4: 31000 | J4: 81 | K4: 81 | L4: 81 | M4: 250 | O4: Altitude | P4: 31000 | Q4: 151 | R4: 151 | S4: 151 | T4: 250
B5: =B4+2000 -> 33000 | C5: 16.5 | D5: 16.5 | E5: 16.5 | F5: 238 | I5: =I4+2000 -> 33000 | J5: 88 | K5: 88 | L5: 88 | M5: 238 | P5: =P4+2000 -> 33000 | Q5: 161 | R5: 161 | S5: 161 | T5: 238
B6: =B5+2000 -> 35000 | C6: 17.5 | D6: 17.5 | E6: 17.5 | F6: 227 | I6: =I5+2000 -> 35000 | J6: 94 | K6: 94 | L6: 94 | M6: 227 | P6: =P5+2000 -> 35000 | Q6: 170 | R6: 170 | S6: 170 | T6: 227
B7: =B6+2000 -> 37000 | C7: 18.5 | D7: 18.5 | E7: 18.5 | F7: 216 | I7: =I6+2000 -> 37000 | J7: 101 | K7: 101 | L7: 101 | M7: 216 | P7: =P6+2000 -> 37000 | Q7: 180 | R7: 180 | S7: 180 | T7: 216
B8: =B7+2000 -> 39000 | C8: 19.5 | D8: 19.5 | E8: 19.5 | F8: 206 | I8: =I7+2000 -> 39000 | J8: 107 | K8: 107 | L8: 107 | M8: 206 | P8: =P7+2000 -> 39000 | Q8: 189 | R8: 189 | S8: 189 | T8: 206
B9: =B8+2000 -> 41000 | C9: 20.5 | D9: 20.5 | E9: 20.5 | F9: 196 | I9: =I8+2000 -> 41000 | J9: 114 | K9: 114 | L9: 114 | M9: 196 | P9: =P8+2000 -> 41000 | Q9: 199 | R9: 199 | S9: 199 | T9: 196
B12: HIGH SPEED DESCENT
C14: Min | J14: Distance (nm) | Q14: Fuel (lbs)
B15: Weight at Descent | C15: not specified | F15: KIAS | I15: Weight at Descent | J15: not specified | M15: KIAS | P15: Weight at Descent | Q15: not specified | T15: KIAS
A16: Altitude | B16: 31000 | C16: 10.3 | D16: 10.3 | E16: 10.3 | F16: 250 | H16: Altitude | I16: 31000 | J16: 54 | K16: 54 | L16: 54 | M16: 250 | O16: Altitude | P16: 31000 | Q16: 70 | R16: 70 | S16: 70 | T16: 250
B17: =B16+2000 -> 33000 | C17: 11 | D17: 11 | E17: 11 | F17: 238 | I17: =I16+2000 -> 33000 | J17: 58 | K17: 58 | L17: 58 | M17: 238 | P17: =P16+2000 -> 33000 | Q17: 75 | R17: 75 | S17: 75 | T17: 238
B18: =B17+2000 -> 35000 | C18: 11.7 | D18: 11.7 | E18: 11.7 | F18: 227 | I18: =I17+2000 -> 35000 | J18: 63 | K18: 63 | L18: 63 | M18: 227 | P18: =P17+2000 -> 35000 | Q18: 80 | R18: 80 | S18: 80 | T18: 227
B19: =B18+2000 -> 37000 | C19: 12.3 | D19: 12.3 | E19: 12.3 | F19: 216 | I19: =I18+2000 -> 37000 | J19: 67 | K19: 67 | L19: 67 | M19: 216 | P19: =P18+2000 -> 37000 | Q19: 85 | R19: 85 | S19: 85 | T19: 216
B20: =B19+2000 -> 39000 | C20: 13 | D20: 13 | E20: 13 | F20: 206 | I20: =I19+2000 -> 39000 | J20: 71 | K20: 71 | L20: 71 | M20: 206 | P20: =P19+2000 -> 39000 | Q20: 90 | R20: 90 | S20: 90 | T20: 206
B21: =B20+2000 -> 41000 | C21: 13.7 | D21: 13.7 | E21: 13.7 | F21: 196 | I21: =I20+2000 -> 41000 | J21: 76 | K21: 76 | L21: 76 | M21: 196 | P21: =P20+2000 -> 41000 | Q21: 95 | R21: 95 | S21: 95 | T21: 196

Sheet B.CJ1.A1
Q1: 14% incr from A0
C2: Min | J2: Distance (nm) | Q2: Fuel (lbs)
B3: Weight at Descent | C3: wt not specified | F3: KIAS | I3: Weight at Descent | J3: wt not specified | M3: KIAS | P3: Weight at Descent | Q3: wt not specified | T3: KIAS
A4: Altitude | B4: 31000 | C4: 15.5 | D4: 15.5 | E4: 15.5 | F4: 250 | H4: Altitude | I4: 31000 | J4: 81 | K4: 81 | L4: 81 | M4: 250 | O4: Altitude | P4: 31000 | Q4: =+'B.CJ1.A0'!Q4*1.14 -> 172.14 | R4: =+'B.CJ1.A0'!R4*1.14 -> 172.14 | S4: =+'B.CJ1.A0'!S4*1.14 -> 172.14 | T4: 250
B5: =B4+2000 -> 33000 | C5: 16.5 | D5: 16.5 | E5: 16.5 | F5: 238 | I5: =I4+2000 -> 33000 | J5: 88 | K5: 88 | L5: 88 | M5: 238 | P5: =P4+2000 -> 33000 | Q5: =+'B.CJ1.A0'!Q5*1.14 -> 183.54 | R5: =+'B.CJ1.A0'!R5*1.14 -> 183.54 | S5: =+'B.CJ1.A0'!S5*1.14 -> 183.54 | T5: 238
B6: =B5+2000 -> 35000 | C6: 17.5 | D6: 17.5 | E6: 17.5 | F6: 227 | I6: =I5+2000 -> 35000 | J6: 94 | K6: 94 | L6: 94 | M6: 227 | P6: =P5+2000 -> 35000 | Q6: =+'B.CJ1.A0'!Q6*1.14 -> 193.8 | R6: =+'B.CJ1.A0'!R6*1.14 -> 193.8 | S6: =+'B.CJ1.A0'!S6*1.14 -> 193.8 | T6: 227
B7: =B6+2000 -> 37000 | C7: 18.5 | D7: 18.5 | E7: 18.5 | F7: 216 | I7: =I6+2000 -> 37000 | J7: 101 | K7: 101 | L7: 101 | M7: 216 | P7: =P6+2000 -> 37000 | Q7: =+'B.CJ1.A0'!Q7*1.14 -> 205.2 | R7: =+'B.CJ1.A0'!R7*1.14 -> 205.2 | S7: =+'B.CJ1.A0'!S7*1.14 -> 205.2 | T7: 216
B8: =B7+2000 -> 39000 | C8: 19.5 | D8: 19.5 | E8: 19.5 | F8: 206 | I8: =I7+2000 -> 39000 | J8: 107 | K8: 107 | L8: 107 | M8: 206 | P8: =P7+2000 -> 39000 | Q8: =+'B.CJ1.A0'!Q8*1.14 -> 215.46 | R8: =+'B.CJ1.A0'!R8*1.14 -> 215.46 | S8: =+'B.CJ1.A0'!S8*1.14 -> 215.46 | T8: 206
B9: =B8+2000 -> 41000 | C9: 20.5 | D9: 20.5 | E9: 20.5 | F9: 196 | I9: =I8+2000 -> 41000 | J9: 114 | K9: 114 | L9: 114 | M9: 196 | P9: =P8+2000 -> 41000 | Q9: =+'B.CJ1.A0'!Q9*1.14 -> 226.86 | R9: =+'B.CJ1.A0'!R9*1.14 -> 226.86 | S9: =+'B.CJ1.A0'!S9*1.14 -> 226.86 | T9: 196
B12: HIGH SPEED DESCENT
C14: Min | J14: Distance (nm) | Q14: Fuel (lbs)
B15: Weight at Descent | C15: wt not specified | F15: KIAS | I15: Weight at Descent | J15: wt not specified | M15: KIAS | P15: Weight at Descent | Q15: wt not specified | T15: KIAS
A16: Altitude | B16: 31000 | C16: 10.3 | D16: 10.3 | E16: 10.3 | F16: 250 | H16: Altitude | I16: 31000 | J16: 54 | K16: 54 | L16: 54 | M16: 250 | O16: Altitude | P16: 31000 | Q16: =+'B.CJ1.A0'!Q16*1.14 -> 79.8 | R16: =+'B.CJ1.A0'!R16*1.14 -> 79.8 | S16: =+'B.CJ1.A0'!S16*1.14 -> 79.8 | T16: 250
B17: =B16+2000 -> 33000 | C17: 11 | D17: 11 | E17: 11 | F17: 238 | I17: =I16+2000 -> 33000 | J17: 58 | K17: 58 | L17: 58 | M17: 238 | P17: =P16+2000 -> 33000 | Q17: =+'B.CJ1.A0'!Q17*1.14 -> 85.5 | R17: =+'B.CJ1.A0'!R17*1.14 -> 85.5 | S17: =+'B.CJ1.A0'!S17*1.14 -> 85.5 | T17: 238
B18: =B17+2000 -> 35000 | C18: 11.7 | D18: 11.7 | E18: 11.7 | F18: 227 | I18: =I17+2000 -> 35000 | J18: 63 | K18: 63 | L18: 63 | M18: 227 | P18: =P17+2000 -> 35000 | Q18: =+'B.CJ1.A0'!Q18*1.14 -> 91.2 | R18: =+'B.CJ1.A0'!R18*1.14 -> 91.2 | S18: =+'B.CJ1.A0'!S18*1.14 -> 91.2 | T18: 227
B19: =B18+2000 -> 37000 | C19: 12.3 | D19: 12.3 | E19: 12.3 | F19: 216 | I19: =I18+2000 -> 37000 | J19: 67 | K19: 67 | L19: 67 | M19: 216 | P19: =P18+2000 -> 37000 | Q19: =+'B.CJ1.A0'!Q19*1.14 -> 96.9 | R19: =+'B.CJ1.A0'!R19*1.14 -> 96.9 | S19: =+'B.CJ1.A0'!S19*1.14 -> 96.9 | T19: 216
B20: =B19+2000 -> 39000 | C20: 13 | D20: 13 | E20: 13 | F20: 206 | I20: =I19+2000 -> 39000 | J20: 71 | K20: 71 | L20: 71 | M20: 206 | P20: =P19+2000 -> 39000 | Q20: =+'B.CJ1.A0'!Q20*1.14 -> 102.6 | R20: =+'B.CJ1.A0'!R20*1.14 -> 102.6 | S20: =+'B.CJ1.A0'!S20*1.14 -> 102.6 | T20: 206
B21: =B20+2000 -> 41000 | C21: 13.7 | D21: 13.7 | E21: 13.7 | F21: 196 | I21: =I20+2000 -> 41000 | J21: 76 | K21: 76 | L21: 76 | M21: 196 | P21: =P20+2000 -> 41000 | Q21: =+'B.CJ1.A0'!Q21*1.14 -> 108.3 | R21: =+'B.CJ1.A0'!R21*1.14 -> 108.3 | S21: =+'B.CJ1.A0'!S21*1.14 -> 108.3 | T21: 196

Sheet M.CJ1.A1
Q1: 14% incr from A0
C2: Min | J2: Distance (nm) | Q2: Fuel (lbs)
B3: Weight at Descent | C3: not specified | F3: KIAS | I3: Weight at Descent | J3: not specified | M3: KIAS | P3: Weight at Descent | Q3: not specified | T3: KIAS
A4: Altitude | B4: 31000 | C4: 15.5 | D4: 15.5 | E4: 15.5 | F4: 250 | H4: Altitude | I4: 31000 | J4: 81 | K4: 81 | L4: 81 | M4: 250 | O4: Altitude | P4: 31000 | Q4: =+'M.CJ1.A0'!Q4*1.14 -> 172.14 | R4: =+'M.CJ1.A0'!R4*1.14 -> 172.14 | S4: =+'M.CJ1.A0'!S4*1.14 -> 172.14 | T4: 250
B5: =B4+2000 -> 33000 | C5: 16.5 | D5: 16.5 | E5: 16.5 | F5: 238 | I5: =I4+2000 -> 33000 | J5: 88 | K5: 88 | L5: 88 | M5: 238 | P5: =P4+2000 -> 33000 | Q5: =+'M.CJ1.A0'!Q5*1.14 -> 183.54 | R5: =+'M.CJ1.A0'!R5*1.14 -> 183.54 | S5: =+'M.CJ1.A0'!S5*1.14 -> 183.54 | T5: 238
B6: =B5+2000 -> 35000 | C6: 17.5 | D6: 17.5 | E6: 17.5 | F6: 227 | I6: =I5+2000 -> 35000 | J6: 94 | K6: 94 | L6: 94 | M6: 227 | P6: =P5+2000 -> 35000 | Q6: =+'M.CJ1.A0'!Q6*1.14 -> 193.8 | R6: =+'M.CJ1.A0'!R6*1.14 -> 193.8 | S6: =+'M.CJ1.A0'!S6*1.14 -> 193.8 | T6: 227
B7: =B6+2000 -> 37000 | C7: 18.5 | D7: 18.5 | E7: 18.5 | F7: 216 | I7: =I6+2000 -> 37000 | J7: 101 | K7: 101 | L7: 101 | M7: 216 | P7: =P6+2000 -> 37000 | Q7: =+'M.CJ1.A0'!Q7*1.14 -> 205.2 | R7: =+'M.CJ1.A0'!R7*1.14 -> 205.2 | S7: =+'M.CJ1.A0'!S7*1.14 -> 205.2 | T7: 216
B8: =B7+2000 -> 39000 | C8: 19.5 | D8: 19.5 | E8: 19.5 | F8: 206 | I8: =I7+2000 -> 39000 | J8: 107 | K8: 107 | L8: 107 | M8: 206 | P8: =P7+2000 -> 39000 | Q8: =+'M.CJ1.A0'!Q8*1.14 -> 215.46 | R8: =+'M.CJ1.A0'!R8*1.14 -> 215.46 | S8: =+'M.CJ1.A0'!S8*1.14 -> 215.46 | T8: 206
B9: =B8+2000 -> 41000 | C9: 20.5 | D9: 20.5 | E9: 20.5 | F9: 196 | I9: =I8+2000 -> 41000 | J9: 114 | K9: 114 | L9: 114 | M9: 196 | P9: =P8+2000 -> 41000 | Q9: =+'M.CJ1.A0'!Q9*1.14 -> 226.86 | R9: =+'M.CJ1.A0'!R9*1.14 -> 226.86 | S9: =+'M.CJ1.A0'!S9*1.14 -> 226.86 | T9: 196
B12: HIGH SPEED DESCENT
C14: Min | J14: Distance (nm) | Q14: Fuel (lbs)
B15: Weight at Descent | C15: not specified | F15: KIAS | I15: Weight at Descent | J15: not specified | M15: KIAS | P15: Weight at Descent | Q15: not specified | T15: KIAS
B16: 31000 | C16: 10.3 | D16: 10.3 | E16: 10.3 | F16: 250 | I16: 31000 | J16: 54 | K16: 54 | L16: 54 | M16: 250 | P16: 31000 | Q16: =+'M.CJ1.A0'!Q16*1.14 -> 79.8 | R16: =+'M.CJ1.A0'!R16*1.14 -> 79.8 | S16: =+'M.CJ1.A0'!S16*1.14 -> 79.8 | T16: 250
B17: 33000 | C17: 11 | D17: 11 | E17: 11 | F17: 238 | I17: 33000 | J17: 58 | K17: 58 | L17: 58 | M17: 238 | P17: 33000 | Q17: =+'M.CJ1.A0'!Q17*1.14 -> 85.5 | R17: =+'M.CJ1.A0'!R17*1.14 -> 85.5 | S17: =+'M.CJ1.A0'!S17*1.14 -> 85.5 | T17: 238
A18: Altitude | B18: 35000 | C18: 11.7 | D18: 11.7 | E18: 11.7 | F18: 227 | H18: Altitude | I18: 35000 | J18: 63 | K18: 63 | L18: 63 | M18: 227 | O18: Altitude | P18: 35000 | Q18: =+'M.CJ1.A0'!Q18*1.14 -> 91.2 | R18: =+'M.CJ1.A0'!R18*1.14 -> 91.2 | S18: =+'M.CJ1.A0'!S18*1.14 -> 91.2 | T18: 227
B19: 37000 | C19: 12.3 | D19: 12.3 | E19: 12.3 | F19: 216 | I19: 37000 | J19: 67 | K19: 67 | L19: 67 | M19: 216 | P19: 37000 | Q19: =+'M.CJ1.A0'!Q19*1.14 -> 96.9 | R19: =+'M.CJ1.A0'!R19*1.14 -> 96.9 | S19: =+'M.CJ1.A0'!S19*1.14 -> 96.9 | T19: 216
B20: 39000 | C20: 13 | D20: 13 | E20: 13 | F20: 206 | I20: 39000 | J20: 71 | K20: 71 | L20: 71 | M20: 206 | P20: 39000 | Q20: =+'M.CJ1.A0'!Q20*1.14 -> 102.6 | R20: =+'M.CJ1.A0'!R20*1.14 -> 102.6 | S20: =+'M.CJ1.A0'!S20*1.14 -> 102.6 | T20: 206
B21: 41000 | C21: 13.7 | D21: 13.7 | E21: 13.7 | F21: 196 | I21: 41000 | J21: 76 | K21: 76 | L21: 76 | M21: 196 | P21: 41000 | Q21: =+'M.CJ1.A0'!Q21*1.14 -> 108.3 | R21: =+'M.CJ1.A0'!R21*1.14 -> 108.3 | S21: =+'M.CJ1.A0'!S21*1.14 -> 108.3 | T21: 196

Sheet B.CJ1+.A0
C2: Min | K2: Distance (nm) | S2: Fuel (lbs)
B3: Weight at Descent | C3: 10000 | D3: 9000 | E3: 8000 | F3: 7000 | G3: KIAS | J3: Weight at Descent | K3: 10000 | L3: 9000 | M3: 8000 | N3: 7000 | O3: KIAS | R3: Weight at Descent | S3: 10000 | T3: 9000 | U3: 8000 | V3: 7000 | W3: KIAS
A4: Altitude | B4: 31000 | C4: 15.5 | D4: 15.5 | E4: 15.5 | F4: 15.5 | G4: 250 | I4: Altitude | J4: 31000 | K4: 82 | L4: 82 | M4: 82 | N4: 82 | O4: 250 | Q4: Altitude | R4: 31000 | S4: 162 | T4: 152 | U4: 144 | V4: 138 | W4: 250
B5: =B4+2000 -> 33000 | C5: 16.5 | D5: 16.5 | E5: 16.5 | F5: 16.5 | G5: 238 | J5: =J4+2000 -> 33000 | K5: 88 | L5: 88 | M5: 88 | N5: 88 | O5: 238 | R5: =R4+2000 -> 33000 | S5: 175 | T5: 164 | U5: 155 | V5: 149 | W5: 238
B6: =B5+2000 -> 35000 | C6: 17.5 | D6: 17.5 | E6: 17.5 | F6: 17.5 | G6: 227 | J6: =J5+2000 -> 35000 | K6: 95 | L6: 95 | M6: 95 | N6: 95 | O6: 227 | R6: =R5+2000 -> 35000 | S6: 188 | T6: 175 | U6: 166 | V6: 158 | W6: 227
B7: =B6+2000 -> 37000 | C7: 18.5 | D7: 18.5 | E7: 18.5 | F7: 18.5 | G7: 216 | J7: =J6+2000 -> 37000 | K7: 101 | L7: 101 | M7: 101 | N7: 101 | O7: 216 | R7: =R6+2000 -> 37000 | S7: 201 | T7: 187 | U7: 176 | V7: 168 | W7: 216
B8: =B7+2000 -> 39000 | C8: 19.4 | D8: 19.5 | E8: 19.5 | F8: 19.5 | G8: 206 | J8: =J7+2000 -> 39000 | K8: 107 | L8: 108 | M8: 108 | N8: 108 | O8: 206 | R8: =R7+2000 -> 39000 | S8: 212 | T8: 198 | U8: 186 | V8: 177 | W8: 206
B9: =B8+2000 -> 41000 | C9: 20.1 | D9: 20.4 | E9: 20.5 | F9: 20.5 | G9: 196 | J9: =J8+2000 -> 41000 | K9: 111 | L9: 113 | M9: 114 | N9: 114 | O9: 196 | R9: =R8+2000 -> 41000 | S9: 220 | T9: 208 | U9: 196 | V9: 185 | W9: 196
B12: HIGH SPEED DESCENT
C14: Min | K14: Distance (nm) | S14: Fuel (lbs)
B15: Weight at Descent | C15: 10000 | D15: 9000 | E15: 8000 | F15: 7000 | G15: KIAS | J15: Weight at Descent | K15: 10000 | L15: 9000 | M15: 8000 | N15: 7000 | O15: KIAS | R15: Weight at Descent | S15: 10000 | T15: 9000 | U15: 8000 | V15: 7000 | W15: KIAS
A16: Altitude | B16: 31000 | C16: 10.3 | D16: 10.3 | E16: 10.3 | F16: 10.3 | G16: 250 | I16: Altitude | J16: 31000 | K16: 54 | L16: 54 | M16: 54 | N16: 54 | O16: 250 | Q16: Altitude | R16: 31000 | S16: 66 | T16: 63 | U16: 61 | V16: 62 | W16: 250
B17: =B16+2000 -> 33000 | C17: 11 | D17: 11 | E17: 11 | F17: 11 | G17: 238 | J17: =J16+2000 -> 33000 | K17: 59 | L17: 59 | M17: 59 | N17: 59 | O17: 238 | R17: =R16+2000 -> 33000 | S17: 73 | T17: 69 | U17: 68 | V17: 68 | W17: 238
B18: =B17+2000 -> 35000 | C18: 11.7 | D18: 11.7 | E18: 11.7 | F18: 11.7 | G18: 227 | J18: =J17+2000 -> 35000 | K18: 63 | L18: 63 | M18: 63 | N18: 63 | O18: 227 | R18: =R17+2000 -> 35000 | S18: 80 | T18: 76 | U18: 73 | V18: 73 | W18: 227
B19: =B18+2000 -> 37000 | C19: 12.3 | D19: 12.3 | E19: 12.3 | F19: 12.3 | G19: 216 | J19: =J18+2000 -> 37000 | K19: 67 | L19: 67 | M19: 67 | N19: 67 | O19: 216 | R19: =R18+2000 -> 37000 | S19: 87 | T19: 82 | U19: 79 | V19: 78 | W19: 216
B20: =B19+2000 -> 39000 | C20: 13 | D20: 13 | E20: 13 | F20: 13 | G20: 206 | J20: =J19+2000 -> 39000 | K20: 72 | L20: 72 | M20: 72 | N20: 72 | O20: 206 | R20: =R19+2000 -> 39000 | S20: 93 | T20: 88 | U20: 84 | V20: 83 | W20: 206
B21: =B20+2000 -> 41000 | C21: 13.7 | D21: 13.7 | E21: 13.7 | F21: 13.7 | G21: 196 | J21: =J20+2000 -> 41000 | K21: 76 | L21: 76 | M21: 76 | N21: 76 | O21: 196 | R21: =R20+2000 -> 41000 | S21: 100 | T21: 94 | U21: 89 | V21: 88 | W21: 196

Sheet M.CJ1+.A0
C2: Min | K2: Distance (nm) | S2: Fuel (lbs)
B3: Weight at Descent | C3: 10000 | D3: 9000 | E3: 8000 | F3: 7000 | G3: KIAS | J3: Weight at Descent | K3: 10000 | L3: 9000 | M3: 8000 | N3: 7000 | O3: KIAS | R3: Weight at Descent | S3: 10000 | T3: 9000 | U3: 8000 | V3: 7000 | W3: KIAS
A4: Altitude | B4: 31000 | C4: 15.5 | D4: 15.5 | E4: 15.5 | F4: 15.5 | G4: 250 | I4: Altitude | J4: 31000 | K4: 82 | L4: 82 | M4: 82 | N4: 82 | O4: 250 | Q4: Altitude | R4: 31000 | S4: 162 | T4: 152 | U4: 144 | V4: 138 | W4: 250
B5: =B4+2000 -> 33000 | C5: 16.5 | D5: 16.5 | E5: 16.5 | F5: 16.5 | G5: 238 | J5: =J4+2000 -> 33000 | K5: 88 | L5: 88 | M5: 88 | N5: 88 | O5: 238 | R5: =R4+2000 -> 33000 | S5: 175 | T5: 164 | U5: 155 | V5: 149 | W5: 238
B6: =B5+2000 -> 35000 | C6: 17.5 | D6: 17.5 | E6: 17.5 | F6: 17.5 | G6: 227 | J6: =J5+2000 -> 35000 | K6: 95 | L6: 95 | M6: 95 | N6: 95 | O6: 227 | R6: =R5+2000 -> 35000 | S6: 188 | T6: 175 | U6: 166 | V6: 158 | W6: 227
B7: =B6+2000 -> 37000 | C7: 18.5 | D7: 18.5 | E7: 18.5 | F7: 18.5 | G7: 216 | J7: =J6+2000 -> 37000 | K7: 101 | L7: 101 | M7: 101 | N7: 101 | O7: 216 | R7: =R6+2000 -> 37000 | S7: 201 | T7: 187 | U7: 176 | V7: 168 | W7: 216
B8: =B7+2000 -> 39000 | C8: 19.4 | D8: 19.5 | E8: 19.5 | F8: 19.5 | G8: 206 | J8: =J7+2000 -> 39000 | K8: 107 | L8: 108 | M8: 108 | N8: 108 | O8: 206 | R8: =R7+2000 -> 39000 | S8: 212 | T8: 198 | U8: 186 | V8: 177 | W8: 206
B9: =B8+2000 -> 41000 | C9: 20.1 | D9: 20.4 | E9: 20.5 | F9: 20.5 | G9: 196 | J9: =J8+2000 -> 41000 | K9: 111 | L9: 113 | M9: 114 | N9: 114 | O9: 196 | R9: =R8+2000 -> 41000 | S9: 220 | T9: 208 | U9: 196 | V9: 185 | W9: 196
B12: HIGH SPEED DESCENT
C14: Min | K14: Distance (nm) | S14: Fuel (lbs)
B15: Weight at Descent | C15: 10000 | D15: 9000 | E15: 8000 | F15: 7000 | G15: KIAS | J15: Weight at Descent | K15: 10000 | L15: 9000 | M15: 8000 | N15: 7000 | O15: KIAS | R15: Weight at Descent | S15: 10000 | T15: 9000 | U15: 8000 | V15: 7000 | W15: KIAS
A16: Altitude | B16: 31000 | C16: 10.3 | D16: 10.3 | E16: 10.3 | F16: 10.3 | G16: 250 | I16: Altitude | J16: 31000 | K16: 54 | L16: 54 | M16: 54 | N16: 54 | O16: 250 | Q16: Altitude | R16: 31000 | S16: 66 | T16: 63 | U16: 61 | V16: 62 | W16: 250
B17: =B16+2000 -> 33000 | C17: 11 | D17: 11 | E17: 11 | F17: 11 | G17: 238 | J17: =J16+2000 -> 33000 | K17: 59 | L17: 59 | M17: 59 | N17: 59 | O17: 238 | R17: =R16+2000 -> 33000 | S17: 73 | T17: 69 | U17: 68 | V17: 68 | W17: 238
B18: =B17+2000 -> 35000 | C18: 11.7 | D18: 11.7 | E18: 11.7 | F18: 11.7 | G18: 227 | J18: =J17+2000 -> 35000 | K18: 63 | L18: 63 | M18: 63 | N18: 63 | O18: 227 | R18: =R17+2000 -> 35000 | S18: 80 | T18: 76 | U18: 73 | V18: 73 | W18: 227
B19: =B18+2000 -> 37000 | C19: 12.3 | D19: 12.3 | E19: 12.3 | F19: 12.3 | G19: 216 | J19: =J18+2000 -> 37000 | K19: 67 | L19: 67 | M19: 67 | N19: 67 | O19: 216 | R19: =R18+2000 -> 37000 | S19: 87 | T19: 82 | U19: 79 | V19: 78 | W19: 216
B20: =B19+2000 -> 39000 | C20: 13 | D20: 13 | E20: 13 | F20: 13 | G20: 206 | J20: =J19+2000 -> 39000 | K20: 72 | L20: 72 | M20: 72 | N20: 72 | O20: 206 | R20: =R19+2000 -> 39000 | S20: 93 | T20: 88 | U20: 84 | V20: 83 | W20: 206
B21: =B20+2000 -> 41000 | C21: 13.7 | D21: 13.7 | E21: 13.7 | F21: 13.7 | G21: 196 | J21: =J20+2000 -> 41000 | K21: 76 | L21: 76 | M21: 76 | N21: 76 | O21: 196 | R21: =R20+2000 -> 41000 | S21: 100 | T21: 94 | U21: 89 | V21: 88 | W21: 196

Sheet B.CJ1+.A1
C2: Min | K2: Distance (nm) | S2: Fuel (lbs)
B3: Weight at Descent | C3: 10000 | D3: 9000 | E3: 8000 | F3: 7000 | G3: KIAS | J3: Weight at Descent | K3: 10000 | L3: 9000 | M3: 8000 | N3: 7000 | O3: KIAS | R3: Weight at Descent | S3: 10000 | T3: 9000 | U3: 8000 | V3: 7000 | W3: KIAS
A4: Altitude | B4: 31000 | C4: 15.5 | D4: 15.5 | E4: 15.5 | F4: 15.5 | G4: 250 | I4: Altitude | J4: 31000 | K4: 82 | L4: 82 | M4: 82 | N4: 82 | O4: 250 | Q4: Altitude | R4: 31000 | S4: 180 | T4: 170 | U4: 161 | V4: 156 | W4: 250
B5: =B4+2000 -> 33000 | C5: 16.5 | D5: 16.5 | E5: 16.5 | F5: 16.5 | G5: 238 | J5: =J4+2000 -> 33000 | K5: 88 | L5: 88 | M5: 88 | N5: 88 | O5: 238 | R5: =R4+2000 -> 33000 | S5: 195 | T5: 183 | U5: 174 | V5: 167 | W5: 238
B6: =B5+2000 -> 35000 | C6: 17.5 | D6: 17.5 | E6: 17.5 | F6: 17.5 | G6: 227 | J6: =J5+2000 -> 35000 | K6: 95 | L6: 95 | M6: 95 | N6: 95 | O6: 227 | R6: =R5+2000 -> 35000 | S6: 209 | T6: 196 | U6: 186 | V6: 178 | W6: 227
B7: =B6+2000 -> 37000 | C7: 18.4 | D7: 18.5 | E7: 18.5 | F7: 18.5 | G7: 216 | J7: =J6+2000 -> 37000 | K7: 100 | L7: 101 | M7: 101 | N7: 101 | O7: 216 | R7: =R6+2000 -> 37000 | S7: 220 | T7: 208 | U7: 197 | V7: 189 | W7: 216
B8: =B7+2000 -> 39000 | C8: 19.1 | D8: 19.4 | E8: 19.5 | F8: 19.5 | G8: 206 | J8: =J7+2000 -> 39000 | K8: 105 | L8: 107 | M8: 108 | N8: 108 | O8: 206 | R8: =R7+2000 -> 39000 | S8: 228 | T8: 219 | U8: 208 | V8: 199 | W8: 206
B9: =B8+2000 -> 41000 | C9: 19.6 | D9: 20.1 | E9: 20.3 | F9: 20.5 | G9: 196 | J9: =J8+2000 -> 41000 | K9: 109 | L9: 111 | M9: 113 | N9: 114 | O9: 196 | R9: =R8+2000 -> 41000 | S9: 234 | T9: 226 | U9: 217 | V9: 209 | W9: 196
B12: HIGH SPEED DESCENT
C14: Min | K14: Distance (nm) | S14: Fuel (lbs)
B15: Weight at Descent | C15: 10000 | D15: 9000 | E15: 8000 | F15: 7000 | G15: KIAS | J15: Weight at Descent | K15: 10000 | L15: 9000 | M15: 8000 | N15: 7000 | O15: KIAS | R15: Weight at Descent | S15: 10000 | T15: 9000 | U15: 8000 | V15: 7000 | W15: KIAS
A16: Altitude | B16: 31000 | C16: 10.7 | D16: 10.8 | E16: 10.9 | F16: 10.9 | G16: 250 | I16: Altitude | J16: 31000 | K16: 56 | L16: 57 | M16: 57 | N16: 57 | O16: 250 | Q16: Altitude | R16: 31000 | S16: 86 | T16: 84 | U16: 82 | V16: 82 | W16: 250
B17: =B16+2000 -> 33000 | C17: 11.4 | D17: 11.5 | E17: 11.5 | F17: 11.5 | G17: 238 | J17: =J16+2000 -> 33000 | K17: 61 | L17: 61 | M17: 61 | N17: 61 | O17: 238 | R17: =R16+2000 -> 33000 | S17: 94 | T17: 91 | U17: 89 | V17: 88 | W17: 238
B18: =B17+2000 -> 35000 | C18: 12.1 | D18: 12.2 | E18: 12.2 | F18: 12.2 | G18: 227 | J18: =J17+2000 -> 35000 | K18: 65 | L18: 65 | M18: 65 | N18: 65 | O18: 227 | R18: =R17+2000 -> 35000 | S18: 101 | T18: 98 | U18: 96 | V18: 95 | W18: 227
B19: =B18+2000 -> 37000 | C19: 12.7 | D19: 12.8 | E19: 12.9 | F19: 12.9 | G19: 216 | J19: =J18+2000 -> 37000 | K19: 69 | L19: 70 | M19: 70 | N19: 70 | O19: 216 | R19: =R18+2000 -> 37000 | S19: 109 | T19: 105 | U19: 102 | V19: 100 | W19: 216
B20: =B19+2000 -> 39000 | C20: 13.4 | D20: 13.5 | E20: 13.5 | F20: 13.5 | G20: 206 | J20: =J19+2000 -> 39000 | K20: 73 | L20: 74 | M20: 74 | N20: 74 | O20: 206 | R20: =R19+2000 -> 39000 | S20: 116 | T20: 112 | U20: 108 | V20: 106 | W20: 206
B21: =B20+2000 -> 41000 | C21: 14 | D21: 14.1 | E21: 14.2 | F21: 14.2 | G21: 196 | J21: =J20+2000 -> 41000 | K21: 77 | L21: 78 | M21: 78 | N21: 78 | O21: 196 | R21: =R20+2000 -> 41000 | S21: 122 | T21: 119 | U21: 115 | V21: 111 | W21: 196

Sheet M.CJ1+.A1
C2: Min | K2: Distance (nm) | S2: Fuel (lbs)
B3: Weight at Descent | C3: 10000 | D3: 9000 | E3: 8000 | F3: 7000 | G3: KIAS | J3: Weight at Descent | K3: 10000 | L3: 9000 | M3: 8000 | N3: 7000 | O3: KIAS | R3: Weight at Descent | S3: 10000 | T3: 9000 | U3: 8000 | V3: 7000 | W3: KIAS
A4: Altitude | B4: 31000 | C4: =+'B.CJ1+.A1'!C4 -> 15.5 | D4: =+'B.CJ1+.A1'!D4 -> 15.5 | E4: =+'B.CJ1+.A1'!E4 -> 15.5 | F4: =+'B.CJ1+.A1'!F4 -> 15.5 | G4: 250 | I4: Altitude | J4: 31000 | K4: =+'B.CJ1+.A1'!K4 -> 82 | L4: =+'B.CJ1+.A1'!L4 -> 82 | M4: =+'B.CJ1+.A1'!M4 -> 82 | N4: =+'B.CJ1+.A1'!N4 -> 82 | O4: 250 | Q4: Altitude | R4: 31000 | S4: =+'B.CJ1+.A1'!S4 -> 180 | T4: =+'B.CJ1+.A1'!T4 -> 170 | U4: =+'B.CJ1+.A1'!U4 -> 161 | V4: =+'B.CJ1+.A1'!V4 -> 156 | W4: 250
B5: =B4+2000 -> 33000 | C5: =+'B.CJ1+.A1'!C5 -> 16.5 | D5: =+'B.CJ1+.A1'!D5 -> 16.5 | E5: =+'B.CJ1+.A1'!E5 -> 16.5 | F5: =+'B.CJ1+.A1'!F5 -> 16.5 | G5: 238 | J5: =J4+2000 -> 33000 | K5: =+'B.CJ1+.A1'!K5 -> 88 | L5: =+'B.CJ1+.A1'!L5 -> 88 | M5: =+'B.CJ1+.A1'!M5 -> 88 | N5: =+'B.CJ1+.A1'!N5 -> 88 | O5: 238 | R5: =R4+2000 -> 33000 | S5: =+'B.CJ1+.A1'!S5 -> 195 | T5: =+'B.CJ1+.A1'!T5 -> 183 | U5: =+'B.CJ1+.A1'!U5 -> 174 | V5: =+'B.CJ1+.A1'!V5 -> 167 | W5: 238
B6: =B5+2000 -> 35000 | C6: =+'B.CJ1+.A1'!C6 -> 17.5 | D6: =+'B.CJ1+.A1'!D6 -> 17.5 | E6: =+'B.CJ1+.A1'!E6 -> 17.5 | F6: =+'B.CJ1+.A1'!F6 -> 17.5 | G6: 227 | J6: =J5+2000 -> 35000 | K6: =+'B.CJ1+.A1'!K6 -> 95 | L6: =+'B.CJ1+.A1'!L6 -> 95 | M6: =+'B.CJ1+.A1'!M6 -> 95 | N6: =+'B.CJ1+.A1'!N6 -> 95 | O6: 227 | R6: =R5+2000 -> 35000 | S6: =+'B.CJ1+.A1'!S6 -> 209 | T6: =+'B.CJ1+.A1'!T6 -> 196 | U6: =+'B.CJ1+.A1'!U6 -> 186 | V6: =+'B.CJ1+.A1'!V6 -> 178 | W6: 227
B7: =B6+2000 -> 37000 | C7: =+'B.CJ1+.A1'!C7 -> 18.4 | D7: =+'B.CJ1+.A1'!D7 -> 18.5 | E7: =+'B.CJ1+.A1'!E7 -> 18.5 | F7: =+'B.CJ1+.A1'!F7 -> 18.5 | G7: 216 | J7: =J6+2000 -> 37000 | K7: =+'B.CJ1+.A1'!K7 -> 100 | L7: =+'B.CJ1+.A1'!L7 -> 101 | M7: =+'B.CJ1+.A1'!M7 -> 101 | N7: =+'B.CJ1+.A1'!N7 -> 101 | O7: 216 | R7: =R6+2000 -> 37000 | S7: =+'B.CJ1+.A1'!S7 -> 220 | T7: =+'B.CJ1+.A1'!T7 -> 208 | U7: =+'B.CJ1+.A1'!U7 -> 197 | V7: =+'B.CJ1+.A1'!V7 -> 189 | W7: 216
B8: =B7+2000 -> 39000 | C8: =+'B.CJ1+.A1'!C8 -> 19.1 | D8: =+'B.CJ1+.A1'!D8 -> 19.4 | E8: =+'B.CJ1+.A1'!E8 -> 19.5 | F8: =+'B.CJ1+.A1'!F8 -> 19.5 | G8: 206 | J8: =J7+2000 -> 39000 | K8: =+'B.CJ1+.A1'!K8 -> 105 | L8: =+'B.CJ1+.A1'!L8 -> 107 | M8: =+'B.CJ1+.A1'!M8 -> 108 | N8: =+'B.CJ1+.A1'!N8 -> 108 | O8: 206 | R8: =R7+2000 -> 39000 | S8: =+'B.CJ1+.A1'!S8 -> 228 | T8: =+'B.CJ1+.A1'!T8 -> 219 | U8: =+'B.CJ1+.A1'!U8 -> 208 | V8: =+'B.CJ1+.A1'!V8 -> 199 | W8: 206
B9: =B8+2000 -> 41000 | C9: =+'B.CJ1+.A1'!C9 -> 19.6 | D9: =+'B.CJ1+.A1'!D9 -> 20.1 | E9: =+'B.CJ1+.A1'!E9 -> 20.3 | F9: =+'B.CJ1+.A1'!F9 -> 20.5 | G9: 196 | J9: =J8+2000 -> 41000 | K9: =+'B.CJ1+.A1'!K9 -> 109 | L9: =+'B.CJ1+.A1'!L9 -> 111 | M9: =+'B.CJ1+.A1'!M9 -> 113 | N9: =+'B.CJ1+.A1'!N9 -> 114 | O9: 196 | R9: =R8+2000 -> 41000 | S9: =+'B.CJ1+.A1'!S9 -> 234 | T9: =+'B.CJ1+.A1'!T9 -> 226 | U9: =+'B.CJ1+.A1'!U9 -> 217 | V9: =+'B.CJ1+.A1'!V9 -> 209 | W9: 196
B12: HIGH SPEED DESCENT
C14: Min | K14: Distance (nm) | S14: Fuel (lbs)
B15: Weight at Descent | C15: 10000 | D15: 9000 | E15: 8000 | F15: 7000 | G15: KIAS | J15: Weight at Descent | K15: 10000 | L15: 9000 | M15: 8000 | N15: 7000 | O15: KIAS | R15: Weight at Descent | S15: 10000 | T15: 9000 | U15: 8000 | V15: 7000 | W15: KIAS
A16: Altitude | B16: 31000 | C16: =+'B.CJ1+.A1'!C16 -> 10.7 | D16: =+'B.CJ1+.A1'!D16 -> 10.8 | E16: =+'B.CJ1+.A1'!E16 -> 10.9 | F16: =+'B.CJ1+.A1'!F16 -> 10.9 | G16: 250 | I16: Altitude | J16: 31000 | K16: =+'B.CJ1+.A1'!K16 -> 56 | L16: =+'B.CJ1+.A1'!L16 -> 57 | M16: =+'B.CJ1+.A1'!M16 -> 57 | N16: =+'B.CJ1+.A1'!N16 -> 57 | O16: 250 | Q16: Altitude | R16: 31000 | S16: =+'B.CJ1+.A1'!S16 -> 86 | T16: =+'B.CJ1+.A1'!T16 -> 84 | U16: =+'B.CJ1+.A1'!U16 -> 82 | V16: =+'B.CJ1+.A1'!V16 -> 82 | W16: 250
B17: =B16+2000 -> 33000 | C17: =+'B.CJ1+.A1'!C17 -> 11.4 | D17: =+'B.CJ1+.A1'!D17 -> 11.5 | E17: =+'B.CJ1+.A1'!E17 -> 11.5 | F17: =+'B.CJ1+.A1'!F17 -> 11.5 | G17: 238 | J17: =J16+2000 -> 33000 | K17: =+'B.CJ1+.A1'!K17 -> 61 | L17: =+'B.CJ1+.A1'!L17 -> 61 | M17: =+'B.CJ1+.A1'!M17 -> 61 | N17: =+'B.CJ1+.A1'!N17 -> 61 | O17: 238 | R17: =R16+2000 -> 33000 | S17: =+'B.CJ1+.A1'!S17 -> 94 | T17: =+'B.CJ1+.A1'!T17 -> 91 | U17: =+'B.CJ1+.A1'!U17 -> 89 | V17: =+'B.CJ1+.A1'!V17 -> 88 | W17: 238
B18: =B17+2000 -> 35000 | C18: =+'B.CJ1+.A1'!C18 -> 12.1 | D18: =+'B.CJ1+.A1'!D18 -> 12.2 | E18: =+'B.CJ1+.A1'!E18 -> 12.2 | F18: =+'B.CJ1+.A1'!F18 -> 12.2 | G18: 227 | J18: =J17+2000 -> 35000 | K18: =+'B.CJ1+.A1'!K18 -> 65 | L18: =+'B.CJ1+.A1'!L18 -> 65 | M18: =+'B.CJ1+.A1'!M18 -> 65 | N18: =+'B.CJ1+.A1'!N18 -> 65 | O18: 227 | R18: =R17+2000 -> 35000 | S18: =+'B.CJ1+.A1'!S18 -> 101 | T18: =+'B.CJ1+.A1'!T18 -> 98 | U18: =+'B.CJ1+.A1'!U18 -> 96 | V18: =+'B.CJ1+.A1'!V18 -> 95 | W18: 227
B19: =B18+2000 -> 37000 | C19: =+'B.CJ1+.A1'!C19 -> 12.7 | D19: =+'B.CJ1+.A1'!D19 -> 12.8 | E19: =+'B.CJ1+.A1'!E19 -> 12.9 | F19: =+'B.CJ1+.A1'!F19 -> 12.9 | G19: 216 | J19: =J18+2000 -> 37000 | K19: =+'B.CJ1+.A1'!K19 -> 69 | L19: =+'B.CJ1+.A1'!L19 -> 70 | M19: =+'B.CJ1+.A1'!M19 -> 70 | N19: =+'B.CJ1+.A1'!N19 -> 70 | O19: 216 | R19: =R18+2000 -> 37000 | S19: =+'B.CJ1+.A1'!S19 -> 109 | T19: =+'B.CJ1+.A1'!T19 -> 105 | U19: =+'B.CJ1+.A1'!U19 -> 102 | V19: =+'B.CJ1+.A1'!V19 -> 100 | W19: 216
B20: =B19+2000 -> 39000 | C20: =+'B.CJ1+.A1'!C20 -> 13.4 | D20: =+'B.CJ1+.A1'!D20 -> 13.5 | E20: =+'B.CJ1+.A1'!E20 -> 13.5 | F20: =+'B.CJ1+.A1'!F20 -> 13.5 | G20: 206 | J20: =J19+2000 -> 39000 | K20: =+'B.CJ1+.A1'!K20 -> 73 | L20: =+'B.CJ1+.A1'!L20 -> 74 | M20: =+'B.CJ1+.A1'!M20 -> 74 | N20: =+'B.CJ1+.A1'!N20 -> 74 | O20: 206 | R20: =R19+2000 -> 39000 | S20: =+'B.CJ1+.A1'!S20 -> 116 | T20: =+'B.CJ1+.A1'!T20 -> 112 | U20: =+'B.CJ1+.A1'!U20 -> 108 | V20: =+'B.CJ1+.A1'!V20 -> 106 | W20: 206
B21: =B20+2000 -> 41000 | C21: =+'B.CJ1+.A1'!C21 -> 14 | D21: =+'B.CJ1+.A1'!D21 -> 14.1 | E21: =+'B.CJ1+.A1'!E21 -> 14.2 | F21: =+'B.CJ1+.A1'!F21 -> 14.2 | G21: 196 | J21: =J20+2000 -> 41000 | K21: =+'B.CJ1+.A1'!K21 -> 77 | L21: =+'B.CJ1+.A1'!L21 -> 78 | M21: =+'B.CJ1+.A1'!M21 -> 78 | N21: =+'B.CJ1+.A1'!N21 -> 78 | O21: 196 | R21: =R20+2000 -> 41000 | S21: =+'B.CJ1+.A1'!S21 -> 122 | T21: =+'B.CJ1+.A1'!T21 -> 119 | U21: =+'B.CJ1+.A1'!U21 -> 115 | V21: =+'B.CJ1+.A1'!V21 -> 111 | W21: 196

Sheet B.M2.A0
C2: Min | K2: Distance (nm) | S2: Fuel (lbs)
B3: Weight at Descent | C3: 10000 | D3: 9000 | E3: 8000 | F3: 7000 | G3: KIAS | J3: Weight at Descent | K3: 10000 | L3: 9000 | M3: 8000 | N3: 7000 | O3: KIAS | R3: Weight at Descent | S3: 10000 | T3: 9000 | U3: 8000 | V3: 7000 | W3: KIAS
A4: Altitude | B4: 31000 | C4: 15.5 | D4: 15.5 | E4: 15.5 | F4: 15.5 | G4: 250 | I4: Altitude | J4: 31000 | K4: 82 | L4: 82 | M4: 82 | N4: 82 | O4: 250 | Q4: Altitude | R4: 31000 | S4: 155 | T4: 144 | U4: 136 | V4: 131 | W4: 250
B5: =B4+2000 -> 33000 | C5: 16.5 | D5: 16.5 | E5: 16.5 | F5: 16.5 | G5: 238 | J5: =J4+2000 -> 33000 | K5: 88 | L5: 88 | M5: 88 | N5: 88 | O5: 238 | R5: =R4+2000 -> 33000 | S5: 167 | T5: 156 | U5: 147 | V5: 141 | W5: 238
B6: =B5+2000 -> 35000 | C6: 17.5 | D6: 17.5 | E6: 17.5 | F6: 17.5 | G6: 227 | J6: =J5+2000 -> 35000 | K6: 95 | L6: 95 | M6: 95 | N6: 95 | O6: 227 | R6: =R5+2000 -> 35000 | S6: 180 | T6: 167 | U6: 158 | V6: 150 | W6: 227
B7: =B6+2000 -> 37000 | C7: 18.5 | D7: 18.5 | E7: 18.5 | F7: 18.5 | G7: 216 | J7: =J6+2000 -> 37000 | K7: 101 | L7: 101 | M7: 101 | N7: 101 | O7: 216 | R7: =R6+2000 -> 37000 | S7: 192 | T7: 178 | U7: 167 | V7: 160 | W7: 216
B8: =B7+2000 -> 39000 | C8: 19.5 | D8: 19.5 | E8: 19.5 | F8: 19.5 | G8: 206 | J8: =J7+2000 -> 39000 | K8: 107 | L8: 108 | M8: 108 | N8: 108 | O8: 206 | R8: =R7+2000 -> 39000 | S8: 204 | T8: 189 | U8: 177 | V8: 168 | W8: 206
B9: =B8+2000 -> 41000 | C9: 20.3 | D9: 20.5 | E9: 20.5 | F9: 20.5 | G9: 196 | J9: =J8+2000 -> 41000 | K9: 112 | L9: 114 | M9: 114 | N9: 114 | O9: 196 | R9: =R8+2000 -> 41000 | S9: 213 | T9: 200 | U9: 187 | V9: 177 | W9: 196
B12: HIGH SPEED DESCENT
C14: Min | K14: Distance (nm) | S14: Fuel (lbs)
B15: Weight at Descent | C15: 10000 | D15: 9000 | E15: 8000 | F15: 7000 | G15: KIAS | J15: Weight at Descent | K15: 10000 | L15: 9000 | M15: 8000 | N15: 7000 | O15: KIAS | R15: Weight at Descent | S15: 10000 | T15: 9000 | U15: 8000 | V15: 7000 | W15: KIAS
A16: Altitude | B16: 31000 | C16: 10.3 | D16: 10.3 | E16: 10.3 | F16: 10.3 | G16: 250 | I16: Altitude | J16: 31000 | K16: 54 | L16: 54 | M16: 54 | N16: 54 | O16: 250 | Q16: Altitude | R16: 31000 | S16: 62 | T16: 59 | U16: 58 | V16: 58 | W16: 250
B17: =B16+2000 -> 33000 | C17: 11 | D17: 11 | E17: 11 | F17: 11 | G17: 238 | J17: =J16+2000 -> 33000 | K17: 59 | L17: 59 | M17: 59 | N17: 59 | O17: 238 | R17: =R16+2000 -> 33000 | S17: 69 | T17: 66 | U17: 64 | V17: 64 | W17: 238
B18: =B17+2000 -> 35000 | C18: 11.7 | D18: 11.7 | E18: 11.7 | F18: 11.7 | G18: 227 | J18: =J17+2000 -> 35000 | K18: 63 | L18: 63 | M18: 63 | N18: 63 | O18: 227 | R18: =R17+2000 -> 35000 | S18: 76 | T18: 72 | U18: 69 | V18: 69 | W18: 227
B19: =B18+2000 -> 37000 | C19: 12.3 | D19: 12.3 | E19: 12.3 | F19: 12.3 | G19: 216 | J19: =J18+2000 -> 37000 | K19: 67 | L19: 67 | M19: 67 | N19: 67 | O19: 216 | R19: =R18+2000 -> 37000 | S19: 82 | T19: 78 | U19: 75 | V19: 74 | W19: 216
B20: =B19+2000 -> 39000 | C20: 13 | D20: 13 | E20: 13 | F20: 13 | G20: 206 | J20: =J19+2000 -> 39000 | K20: 71 | L20: 71 | M20: 71 | N20: 71 | O20: 206 | R20: =R19+2000 -> 39000 | S20: 89 | T20: 83 | U20: 80 | V20: 78 | W20: 206
B21: =B20+2000 -> 41000 | C21: 13.7 | D21: 13.7 | E21: 13.7 | F21: 13.7 | G21: 196 | J21: =J20+2000 -> 41000 | K21: 76 | L21: 76 | M21: 76 | N21: 76 | O21: 196 | R21: =R20+2000 -> 41000 | S21: 96 | T21: 89 | U21: 85 | V21: 83 | W21: 196

Sheet M.M2.A0
C2: Min | K2: Distance (nm) | S2: Fuel (lbs)
B3: Weight at Descent | C3: 10000 | D3: 9000 | E3: 8000 | F3: 7000 | G3: KIAS | J3: Weight at Descent | K3: 10000 | L3: 9000 | M3: 8000 | N3: 7000 | O3: KIAS | R3: Weight at Descent | S3: 10000 | T3: 9000 | U3: 8000 | V3: 7000 | W3: KIAS
A4: Altitude | B4: 31000 | C4: 15.5 | D4: 15.5 | E4: 15.5 | F4: 15.5 | G4: 250 | I4: Altitude | J4: 31000 | K4: 82 | L4: 82 | M4: 82 | N4: 82 | O4: 250 | Q4: Altitude | R4: 31000 | S4: 155 | T4: 144 | U4: 136 | V4: 131 | W4: 250
B5: =B4+2000 -> 33000 | C5: 16.5 | D5: 16.5 | E5: 16.5 | F5: 16.5 | G5: 238 | J5: =J4+2000 -> 33000 | K5: 88 | L5: 88 | M5: 88 | N5: 88 | O5: 238 | R5: =R4+2000 -> 33000 | S5: 167 | T5: 156 | U5: 147 | V5: 141 | W5: 238
B6: =B5+2000 -> 35000 | C6: 17.5 | D6: 17.5 | E6: 17.5 | F6: 17.5 | G6: 227 | J6: =J5+2000 -> 35000 | K6: 95 | L6: 95 | M6: 95 | N6: 95 | O6: 227 | R6: =R5+2000 -> 35000 | S6: 180 | T6: 167 | U6: 158 | V6: 150 | W6: 227
B7: =B6+2000 -> 37000 | C7: 18.5 | D7: 18.5 | E7: 18.5 | F7: 18.5 | G7: 216 | J7: =J6+2000 -> 37000 | K7: 101 | L7: 101 | M7: 101 | N7: 101 | O7: 216 | R7: =R6+2000 -> 37000 | S7: 192 | T7: 178 | U7: 167 | V7: 160 | W7: 216
B8: =B7+2000 -> 39000 | C8: 19.5 | D8: 19.5 | E8: 19.5 | F8: 19.5 | G8: 206 | J8: =J7+2000 -> 39000 | K8: 107 | L8: 108 | M8: 108 | N8: 108 | O8: 206 | R8: =R7+2000 -> 39000 | S8: 204 | T8: 189 | U8: 177 | V8: 168 | W8: 206
B9: =B8+2000 -> 41000 | C9: 20.3 | D9: 20.5 | E9: 20.5 | F9: 20.5 | G9: 196 | J9: =J8+2000 -> 41000 | K9: 112 | L9: 114 | M9: 114 | N9: 114 | O9: 196 | R9: =R8+2000 -> 41000 | S9: 213 | T9: 200 | U9: 187 | V9: 177 | W9: 196
B12: HIGH SPEED DESCENT
C14: Min | K14: Distance (nm) | S14: Fuel (lbs)
B15: Weight at Descent | C15: 10000 | D15: 9000 | E15: 8000 | F15: 7000 | G15: KIAS | J15: Weight at Descent | K15: 10000 | L15: 9000 | M15: 8000 | N15: 7000 | O15: KIAS | R15: Weight at Descent | S15: 10000 | T15: 9000 | U15: 8000 | V15: 7000 | W15: KIAS
A16: Altitude | B16: 31000 | C16: 10.3 | D16: 10.3 | E16: 10.3 | F16: 10.3 | G16: 250 | I16: Altitude | J16: 31000 | K16: 54 | L16: 54 | M16: 54 | N16: 54 | O16: 250 | Q16: Altitude | R16: 31000 | S16: 62 | T16: 59 | U16: 58 | V16: 58 | W16: 250
B17: =B16+2000 -> 33000 | C17: 11 | D17: 11 | E17: 11 | F17: 11 | G17: 238 | J17: =J16+2000 -> 33000 | K17: 59 | L17: 59 | M17: 59 | N17: 59 | O17: 238 | R17: =R16+2000 -> 33000 | S17: 69 | T17: 66 | U17: 64 | V17: 64 | W17: 238
B18: =B17+2000 -> 35000 | C18: 11.7 | D18: 11.7 | E18: 11.7 | F18: 11.7 | G18: 227 | J18: =J17+2000 -> 35000 | K18: 63 | L18: 63 | M18: 63 | N18: 63 | O18: 227 | R18: =R17+2000 -> 35000 | S18: 76 | T18: 72 | U18: 69 | V18: 69 | W18: 227
B19: =B18+2000 -> 37000 | C19: 12.3 | D19: 12.3 | E19: 12.3 | F19: 12.3 | G19: 216 | J19: =J18+2000 -> 37000 | K19: 67 | L19: 67 | M19: 67 | N19: 67 | O19: 216 | R19: =R18+2000 -> 37000 | S19: 82 | T19: 78 | U19: 75 | V19: 74 | W19: 216
B20: =B19+2000 -> 39000 | C20: 13 | D20: 13 | E20: 13 | F20: 13 | G20: 206 | J20: =J19+2000 -> 39000 | K20: 71 | L20: 71 | M20: 71 | N20: 71 | O20: 206 | R20: =R19+2000 -> 39000 | S20: 89 | T20: 83 | U20: 80 | V20: 78 | W20: 206
B21: =B20+2000 -> 41000 | C21: 13.7 | D21: 13.7 | E21: 13.7 | F21: 13.7 | G21: 196 | J21: =J20+2000 -> 41000 | K21: 76 | L21: 76 | M21: 76 | N21: 76 | O21: 196 | R21: =R20+2000 -> 41000 | S21: 96 | T21: 89 | U21: 85 | V21: 83 | W21: 196

Sheet B.M2.A1
C2: Min | K2: Distance (nm) | S2: Fuel (lbs)
B3: Weight at Descent | C3: 10000 | D3: 9000 | E3: 8000 | F3: 7000 | G3: KIAS | J3: Weight at Descent | K3: 10000 | L3: 9000 | M3: 8000 | N3: 7000 | O3: KIAS | R3: Weight at Descent | S3: 10000 | T3: 9000 | U3: 8000 | V3: 7000 | W3: KIAS
A4: Altitude | B4: 31000 | C4: 15.5 | D4: 15.5 | E4: 15.5 | F4: 15.5 | G4: 250 | I4: Altitude | J4: 31000 | K4: 82 | L4: 82 | M4: 82 | N4: 82 | O4: 250 | Q4: Altitude | R4: 31000 | S4: 173 | T4: 163 | U4: 155 | V4: 149 | W4: 250
B5: =B4+2000 -> 33000 | C5: 16.5 | D5: 16.5 | E5: 16.5 | F5: 16.5 | G5: 238 | J5: =J4+2000 -> 33000 | K5: 88 | L5: 88 | M5: 88 | N5: 88 | O5: 238 | R5: =R4+2000 -> 33000 | S5: 187 | T5: 176 | U5: 167 | V5: 160 | W5: 238
B6: =B5+2000 -> 35000 | C6: 17.5 | D6: 17.5 | E6: 17.5 | F6: 17.5 | G6: 227 | J6: =J5+2000 -> 35000 | K6: 95 | L6: 95 | M6: 95 | N6: 95 | O6: 227 | R6: =R5+2000 -> 35000 | S6: 201 | T6: 188 | U6: 178 | V6: 171 | W6: 227
B7: =B6+2000 -> 37000 | C7: 18.5 | D7: 18.5 | E7: 18.5 | F7: 18.5 | G7: 216 | J7: =J6+2000 -> 37000 | K7: 101 | L7: 101 | M7: 101 | N7: 101 | O7: 216 | R7: =R6+2000 -> 37000 | S7: 214 | T7: 200 | U7: 189 | V7: 181 | W7: 216
B8: =B7+2000 -> 39000 | C8: 19.2 | D8: 19.4 | E8: 19.5 | F8: 19.5 | G8: 206 | J8: =J7+2000 -> 39000 | K8: 106 | L8: 107 | M8: 107 | N8: 107 | O8: 206 | R8: =R7+2000 -> 39000 | S8: 223 | T8: 211 | U8: 200 | V8: 191 | W8: 206
B9: =B8+2000 -> 41000 | C9: 19.8 | D9: 20.2 | E9: 20.4 | F9: 20.5 | G9: 196 | J9: =J8+2000 -> 41000 | K9: 109 | L9: 112 | M9: 113 | N9: 114 | O9: 196 | R9: =R8+2000 -> 41000 | S9: 229 | T9: 219 | U9: 209 | V9: 201 | W9: 196
B12: HIGH SPEED DESCENT
C14: Min | K14: Distance (nm) | S14: Fuel (lbs)
B15: Weight at Descent | C15: 10000 | D15: 9000 | E15: 8000 | F15: 7000 | G15: KIAS | J15: Weight at Descent | K15: 10000 | L15: 9000 | M15: 8000 | N15: 7000 | O15: KIAS | R15: Weight at Descent | S15: 10000 | T15: 9000 | U15: 8000 | V15: 7000 | W15: KIAS
A16: Altitude | B16: 31000 | C16: 10.8 | D16: 10.9 | E16: 11 | F16: 11 | G16: 250 | I16: Altitude | J16: 31000 | K16: 56 | L16: 57 | M16: 57 | N16: 57 | O16: 250 | Q16: Altitude | R16: 31000 | S16: 84 | T16: 82 | U16: 81 | V16: 81 | W16: 250
B17: =B16+2000 -> 33000 | C17: 11.5 | D17: 11.6 | E17: 11.7 | F17: 11.7 | G17: 238 | J17: =J16+2000 -> 33000 | K17: 61 | L17: 61 | M17: 62 | N17: 62 | O17: 238 | R17: =R16+2000 -> 33000 | S17: 92 | T17: 89 | U17: 88 | V17: 87 | W17: 238
B18: =B17+2000 -> 35000 | C18: 12.2 | D18: 12.3 | E18: 12.4 | F18: 12.4 | G18: 227 | J18: =J17+2000 -> 35000 | K18: 65 | L18: 66 | M18: 66 | N18: 66 | O18: 227 | R18: =R17+2000 -> 35000 | S18: 99 | T18: 96 | U18: 94 | V18: 93 | W18: 227
B19: =B18+2000 -> 37000 | C19: 12.8 | D19: 12.9 | E19: 13 | F19: 13 | G19: 216 | J19: =J18+2000 -> 37000 | K19: 69 | L19: 70 | M19: 70 | N19: 70 | O19: 216 | R19: =R18+2000 -> 37000 | S19: 106 | T19: 103 | U19: 100 | V19: 99 | W19: 216
B20: =B19+2000 -> 39000 | C20: 13.5 | D20: 13.6 | E20: 13.7 | F20: 13.7 | G20: 206 | J20: =J19+2000 -> 39000 | K20: 74 | L20: 74 | M20: 74 | N20: 74 | O20: 206 | R20: =R19+2000 -> 39000 | S20: 114 | T20: 110 | U20: 106 | V20: 104 | W20: 206
B21: =B20+2000 -> 41000 | C21: 14.1 | D21: 14.3 | E21: 14.4 | F21: 14.4 | G21: 196 | J21: =J20+2000 -> 41000 | K21: 77 | L21: 78 | M21: 79 | N21: 79 | O21: 196 | R21: =R20+2000 -> 41000 | S21: 120 | T21: 116 | U21: 112 | V21: 109 | W21: 196

Sheet M.M2.A1
C2: Min | K2: Distance (nm) | S2: Fuel (lbs)
B3: Weight at Descent | C3: 10000 | D3: 9000 | E3: 8000 | F3: 7000 | G3: KIAS | J3: Weight at Descent | K3: 10000 | L3: 9000 | M3: 8000 | N3: 7000 | O3: KIAS | R3: Weight at Descent | S3: 10000 | T3: 9000 | U3: 8000 | V3: 7000 | W3: KIAS
A4: Altitude | B4: 31000 | C4: 15.5 | D4: 15.5 | E4: 15.5 | F4: 15.5 | G4: 250 | I4: Altitude | J4: 31000 | K4: 82 | L4: 82 | M4: 82 | N4: 82 | O4: 250 | Q4: Altitude | R4: 31000 | S4: 173 | T4: 163 | U4: 155 | V4: 149 | W4: 250
B5: =B4+2000 -> 33000 | C5: 16.5 | D5: 16.5 | E5: 16.5 | F5: 16.5 | G5: 238 | J5: =J4+2000 -> 33000 | K5: 88 | L5: 88 | M5: 88 | N5: 88 | O5: 238 | R5: =R4+2000 -> 33000 | S5: 187 | T5: 176 | U5: 167 | V5: 160 | W5: 238
B6: =B5+2000 -> 35000 | C6: 17.5 | D6: 17.5 | E6: 17.5 | F6: 17.5 | G6: 227 | J6: =J5+2000 -> 35000 | K6: 95 | L6: 95 | M6: 95 | N6: 95 | O6: 227 | R6: =R5+2000 -> 35000 | S6: 201 | T6: 188 | U6: 178 | V6: 171 | W6: 227
B7: =B6+2000 -> 37000 | C7: 18.5 | D7: 18.5 | E7: 18.5 | F7: 18.5 | G7: 216 | J7: =J6+2000 -> 37000 | K7: 101 | L7: 101 | M7: 101 | N7: 101 | O7: 216 | R7: =R6+2000 -> 37000 | S7: 214 | T7: 200 | U7: 189 | V7: 181 | W7: 216
B8: =B7+2000 -> 39000 | C8: 19.2 | D8: 19.4 | E8: 19.5 | F8: 19.5 | G8: 206 | J8: =J7+2000 -> 39000 | K8: 106 | L8: 107 | M8: 107 | N8: 107 | O8: 206 | R8: =R7+2000 -> 39000 | S8: 223 | T8: 211 | U8: 200 | V8: 191 | W8: 206
B9: =B8+2000 -> 41000 | C9: 19.8 | D9: 20.2 | E9: 20.4 | F9: 20.5 | G9: 196 | J9: =J8+2000 -> 41000 | K9: 109 | L9: 112 | M9: 113 | N9: 114 | O9: 196 | R9: =R8+2000 -> 41000 | S9: 229 | T9: 219 | U9: 209 | V9: 201 | W9: 196
B12: HIGH SPEED DESCENT
C14: Min | K14: Distance (nm) | S14: Fuel (lbs)
B15: Weight at Descent | C15: 10000 | D15: 9000 | E15: 8000 | F15: 7000 | G15: KIAS | J15: Weight at Descent | K15: 10000 | L15: 9000 | M15: 8000 | N15: 7000 | O15: KIAS | R15: Weight at Descent | S15: 10000 | T15: 9000 | U15: 8000 | V15: 7000 | W15: KIAS
A16: Altitude | B16: 31000 | C16: 10.8 | D16: 10.9 | E16: 11 | F16: 11 | G16: 250 | I16: Altitude | J16: 31000 | K16: 56 | L16: 57 | M16: 57 | N16: 57 | O16: 250 | Q16: Altitude | R16: 31000 | S16: 84 | T16: 82 | U16: 81 | V16: 81 | W16: 250
B17: =B16+2000 -> 33000 | C17: 11.5 | D17: 11.6 | E17: 11.7 | F17: 11.7 | G17: 238 | J17: =J16+2000 -> 33000 | K17: 61 | L17: 61 | M17: 62 | N17: 62 | O17: 238 | R17: =R16+2000 -> 33000 | S17: 92 | T17: 89 | U17: 88 | V17: 87 | W17: 238
B18: =B17+2000 -> 35000 | C18: 12.2 | D18: 12.3 | E18: 12.4 | F18: 12.4 | G18: 227 | J18: =J17+2000 -> 35000 | K18: 65 | L18: 66 | M18: 66 | N18: 66 | O18: 227 | R18: =R17+2000 -> 35000 | S18: 99 | T18: 96 | U18: 94 | V18: 93 | W18: 227
B19: =B18+2000 -> 37000 | C19: 12.8 | D19: 12.9 | E19: 13 | F19: 13 | G19: 216 | J19: =J18+2000 -> 37000 | K19: 69 | L19: 70 | M19: 70 | N19: 70 | O19: 216 | R19: =R18+2000 -> 37000 | S19: 106 | T19: 103 | U19: 100 | V19: 99 | W19: 216
B20: =B19+2000 -> 39000 | C20: 13.5 | D20: 13.6 | E20: 13.7 | F20: 13.7 | G20: 206 | J20: =J19+2000 -> 39000 | K20: 74 | L20: 74 | M20: 74 | N20: 74 | O20: 206 | R20: =R19+2000 -> 39000 | S20: 114 | T20: 110 | U20: 106 | V20: 104 | W20: 206
B21: =B20+2000 -> 41000 | C21: 14.1 | D21: 14.3 | E21: 14.4 | F21: 14.4 | G21: 196 | J21: =J20+2000 -> 41000 | K21: 77 | L21: 78 | M21: 79 | N21: 79 | O21: 196 | R21: =R20+2000 -> 41000 | S21: 120 | T21: 116 | U21: 112 | V21: 109 | W21: 196

Sheet B.CJ2.A0
C2: Min | J2: Distance (NM) | Q2: Fuel lbs
B3: Weight at Descent | C3: 11500 | D3: 10000 | E3: 9000 | F3: KIAS | I3: Weight at Descent | J3: 11500 | K3: 10000 | L3: 9000 | M3: KIAS | P3: Weight at Descent | Q3: 11500 | R3: 10000 | S3: 9000 | T3: KIAS
A4: Altitude | B4: 35000 | C4: 17.5 | D4: 17.5 | E4: 17.5 | F4: 229 | H4: Altitude | I4: 35000 | J4: 98 | K4: 98 | L4: 98 | M4: 229 | O4: Altitude | P4: 35000 | Q4: 148 | R4: 161 | S4: 170 | T4: 229
B5: =B4+2000 -> 37000 | C5: 18.5 | D5: 18.5 | E5: 18.5 | F5: 218 | I5: =I4+2000 -> 37000 | J5: 104 | K5: 104 | L5: 104 | M5: 218 | P5: =P4+2000 -> 37000 | Q5: 155 | R5: 168 | S5: 178 | T5: 218
B6: =B5+2000 -> 39000 | C6: 19.5 | D6: 19.5 | E6: 19.5 | F6: 208 | I6: =I5+2000 -> 39000 | J6: 111 | K6: 111 | L6: 111 | M6: 208 | P6: =P5+2000 -> 39000 | Q6: 161 | R6: 174 | S6: 184 | T6: 208
B7: =B6+2000 -> 41000 | C7: 20.5 | D7: 20.5 | E7: 20.5 | F7: 198 | I7: =I6+2000 -> 41000 | J7: 117 | K7: 117 | L7: 117 | M7: 198 | P7: =P6+2000 -> 41000 | Q7: 166 | R7: 180 | S7: 190 | T7: 198
B8: =B7+2000 -> 43000 | C8: 21.5 | D8: 21.5 | E8: 21.5 | F8: 188 | I8: =I7+2000 -> 43000 | J8: 124 | K8: 123 | L8: 123 | M8: 188 | P8: =P7+2000 -> 43000 | Q8: 170 | R8: 185 | S8: 195 | T8: 188
B9: =B8+2000 -> 45000 | C9: 22.5 | D9: 22.5 | E9: 22.5 | F9: 179 | I9: =I8+2000 -> 45000 | J9: 130 | K9: 130 | L9: 130 | M9: 179 | P9: =P8+2000 -> 45000 | Q9: 174 | R9: 189 | S9: 199 | T9: 179
B12: HIGH SPEED DESCENT
C14: Min | J14: Distance (NM) | Q14: Fuel lbs
B15: Weight at Descent | C15: 11500 | D15: 10000 | E15: 9000 | F15: KIAS | I15: Weight at Descent | J15: 11500 | K15: 10000 | L15: 9000 | M15: KIAS | P15: Weight at Descent | Q15: 11500 | R15: 10000 | S15: 9000 | T15: KIAS
A16: Altitude | B16: 35000 | C16: 12.7 | D16: 12.2 | E16: 11.9 | F16: 229 | H16: Altitude | I16: 35000 | J16: 69 | K16: 67 | L16: 66 | M16: 229 | O16: Altitude | P16: 35000 | Q16: 68 | R16: 74 | S16: 79 | T16: 229
B17: =B16+2000 -> 37000 | C17: 13.3 | D17: 12.8 | E17: 12.5 | F17: 218 | I17: =I16+2000 -> 37000 | J17: 74 | K17: 72 | L17: 70 | M17: 218 | P17: =P16+2000 -> 37000 | Q17: 70 | R17: 78 | S17: 83 | T17: 218
B18: =B17+2000 -> 39000 | C18: 14 | D18: 13.5 | E18: 13.2 | F18: 208 | I18: =I17+2000 -> 39000 | J18: 78 | K18: 76 | L18: 74 | M18: 208 | P18: =P17+2000 -> 39000 | Q18: 72 | R18: 80 | S18: 86 | T18: 208
B19: =B18+2000 -> 41000 | C19: 14.7 | D19: 14.2 | E19: 13.9 | F19: 198 | I19: =I18+2000 -> 41000 | J19: 83 | K19: 80 | L19: 79 | M19: 198 | P19: =P18+2000 -> 41000 | Q19: 74 | R19: 82 | S19: 88 | T19: 198
B20: =B19+2000 -> 43000 | C20: 15.5 | D20: 14.9 | E20: 14.6 | F20: 188 | I20: =I19+2000 -> 43000 | J20: 88 | K20: 85 | L20: 83 | M20: 188 | P20: =P19+2000 -> 43000 | Q20: 77 | R20: 84 | S20: 90 | T20: 188
B21: =B20+2000 -> 45000 | C21: 16.4 | D21: 15.7 | E21: 15.3 | F21: 179 | I21: =I20+2000 -> 45000 | J21: 93 | K21: 90 | L21: 88 | M21: 179 | P21: =P20+2000 -> 45000 | Q21: 79 | R21: 86 | S21: 92 | T21: 179

Sheet M.CJ2.A0
C2: Min | J2: Distance (NM) | Q2: Fuel lbs
B3: Weight at Descent | C3: 11500 | D3: 10000 | E3: 9000 | F3: KIAS | I3: Weight at Descent | J3: 11500 | K3: 10000 | L3: 9000 | M3: KIAS | P3: Weight at Descent | Q3: 11500 | R3: 10000 | S3: 9000 | T3: KIAS
A4: Altitude | B4: 35000 | C4: 17.5 | D4: 17.5 | E4: 17.5 | F4: 229 | H4: Altitude | I4: 35000 | J4: 98 | K4: 98 | L4: 98 | M4: 229 | O4: Altitude | P4: 35000 | Q4: 148 | R4: 161 | S4: 170 | T4: 229
B5: =B4+2000 -> 37000 | C5: 18.5 | D5: 18.5 | E5: 18.5 | F5: 218 | I5: =I4+2000 -> 37000 | J5: 104 | K5: 104 | L5: 104 | M5: 218 | P5: =P4+2000 -> 37000 | Q5: 155 | R5: 168 | S5: 178 | T5: 218
B6: =B5+2000 -> 39000 | C6: 19.5 | D6: 19.5 | E6: 19.5 | F6: 208 | I6: =I5+2000 -> 39000 | J6: 111 | K6: 111 | L6: 111 | M6: 208 | P6: =P5+2000 -> 39000 | Q6: 161 | R6: 174 | S6: 184 | T6: 208
B7: =B6+2000 -> 41000 | C7: 20.5 | D7: 20.5 | E7: 20.5 | F7: 198 | I7: =I6+2000 -> 41000 | J7: 117 | K7: 117 | L7: 117 | M7: 198 | P7: =P6+2000 -> 41000 | Q7: 166 | R7: 180 | S7: 190 | T7: 198
B8: =B7+2000 -> 43000 | C8: 21.5 | D8: 21.5 | E8: 21.5 | F8: 188 | I8: =I7+2000 -> 43000 | J8: 124 | K8: 123 | L8: 123 | M8: 188 | P8: =P7+2000 -> 43000 | Q8: 170 | R8: 185 | S8: 195 | T8: 188
B9: =B8+2000 -> 45000 | C9: 22.5 | D9: 22.5 | E9: 22.5 | F9: 179 | I9: =I8+2000 -> 45000 | J9: 130 | K9: 130 | L9: 130 | M9: 179 | P9: =P8+2000 -> 45000 | Q9: 174 | R9: 189 | S9: 199 | T9: 179
B12: HIGH SPEED DESCENT
C14: Min | J14: Distance (NM) | Q14: Fuel lbs
B15: Weight at Descent | C15: 11500 | D15: 10000 | E15: 9000 | F15: KIAS | I15: Weight at Descent | J15: 11500 | K15: 10000 | L15: 9000 | M15: KIAS | P15: Weight at Descent | Q15: 11500 | R15: 10000 | S15: 9000 | T15: KIAS
